<sdf version='1.11'>
  <model name='go2_description'>
    <link name='base'>
      <inertial>
        <pose>0.020153063882401429 0 -0.0051089553510097526 0 0 0</pose>
        <mass>7.2790000000000017</mass>
        <inertia>
          <ixx>0.025737618948512481</ixx>
          <ixy>0.00012166</ixy>
          <ixz>0.001534235398809762</ixz>
          <iyy>0.1031209538931058</iyy>
          <iyz>-3.1199999999999999e-05</iyz>
          <izz>0.1128090234445933</izz>
        </inertia>
      </inertial>
      <collision name='base_collision'>
        <pose>0 0 0 0 0 0</pose>
        <geometry>
          <box>
            <size>0.37619999999999998 0.0935 0.114</size>
          </box>
        </geometry>
      </collision>
      <collision name='base_fixed_joint_lump__Head_upper_collision_1'>
        <pose>0.28499999999999998 0 0.01 0 0 0</pose>
        <geometry>
          <cylinder>
            <length>0.089999999999999997</length>
            <radius>0.050000000000000003</radius>
          </cylinder>
        </geometry>
      </collision>
      <collision name='base_fixed_joint_lump__Head_lower_collision_2'>
        <pose>0.29299999999999998 0 -0.059999999999999998 0 0 0</pose>
        <geometry>
          <sphere>
            <radius>0.047</radius>
          </sphere>
        </geometry>
      </collision>
      <visual name='base_visual'>
        <pose>0 0 0 0 0 0</pose>
        <geometry>
          <mesh>
            <scale>1 1 1</scale>
            <uri>model://go2_description/dae/base.dae</uri>
          </mesh>
        </geometry>
        <material>
          <diffuse>0.839631855 0.86553216 0.967837751 1</diffuse>
          <ambient>0.839631855 0.86553216 0.967837751 1</ambient>
        </material>
      </visual>
    </link>
    <joint name='FL_hip_joint' type='revolute'>
      <pose relative_to='base'>0.19339999999999999 0.0465 0 0 0 0</pose>
      <parent>base</parent>
      <child>FL_hip</child>
      <axis>
        <xyz>1 0 0</xyz>
        <limit>
          <lower>-1.0471999999999999</lower>
          <upper>1.0471999999999999</upper>
          <effort>23.699999999999999</effort>
          <velocity>30.100000000000001</velocity>
        </limit>
        <dynamics>
          <spring_reference>0</spring_reference>
          <spring_stiffness>0</spring_stiffness>
        </dynamics>
      </axis>
    </joint>
    <link name='FL_hip'>
      <pose relative_to='FL_hip_joint'>0 0 0 0 0 0</pose>
      <inertial>
        <pose>-0.0047734028683181226 0.00169748370273794 -9.2816166883963517e-05 0 0 0</pose>
        <mass>0.76700000000000002</mass>
        <inertia>
          <ixx>0.00053999151781062584</ixx>
          <ixy>-2.1220993324641449e-06</ixy>
          <ixz>1.0653925501955671e-06</ixz>
          <iyy>0.00099813696478559337</iyy>
          <iyz>-1.4027352647979141e-06</iyz>
          <izz>0.00065828474786205991</izz>
        </inertia>
      </inertial>
      <collision name='FL_hip_collision'>
        <pose>0 0.080000000000000002 0 1.5707963267948959 0 0</pose>
        <geometry>
          <cylinder>
            <length>0.040000000000000001</length>
            <radius>0.045999999999999999</radius>
          </cylinder>
        </geometry>
      </collision>
      <visual name='FL_hip_visual'>
        <pose>0 0 0 0 0 0</pose>
        <geometry>
          <mesh>
            <scale>1 1 1</scale>
            <uri>model://go2_description/dae/hip.dae</uri>
          </mesh>
        </geometry>
        <material>
          <diffuse>0.839631855 0.86553216 0.967837751 1</diffuse>
          <ambient>0.839631855 0.86553216 0.967837751 1</ambient>
        </material>
      </visual>
    </link>
    <joint name='FL_thigh_joint' type='revolute'>
      <pose relative_to='FL_hip'>0 0.095500000000000002 0 0 0 0</pose>
      <parent>FL_hip</parent>
      <child>FL_thigh</child>
      <axis>
        <xyz>0 1 0</xyz>
        <limit>
          <lower>-1.5708</lower>
          <upper>3.4906999999999999</upper>
          <effort>23.699999999999999</effort>
          <velocity>30.100000000000001</velocity>
        </limit>
        <dynamics>
          <spring_reference>0</spring_reference>
          <spring_stiffness>0</spring_stiffness>
        </dynamics>
      </axis>
    </joint>
    <link name='FL_thigh'>
      <pose relative_to='FL_thigh_joint'>0 0 0 0 0 0</pose>
      <inertial>
        <pose>-0.003471780821917808 -0.02302074939564867 -0.03035487510072523 0 0 0</pose>
        <mass>1.2410000000000001</mass>
        <inertia>
          <ixx>0.0059963333412087023</ixx>
          <ixy>9.0305334356164388e-05</ixy>
          <ixz>-0.00029910392372602731</ixz>
          <iyy>0.0060013394099700237</iyy>
          <iyz>0.00083515091803384382</iyz>
          <izz>0.0010991471651674461</izz>
        </inertia>
      </inertial>
      <collision name='FL_thigh_collision'>
        <pose>0 0 -0.1065 0 1.5707963267948966 0</pose>
        <geometry>
          <box>
            <size>0.21299999999999999 0.024500000000000001 0.034000000000000002</size>
          </box>
        </geometry>
      </collision>
      <visual name='FL_thigh_visual'>
        <pose>0 0 0 0 0 0</pose>
        <geometry>
          <mesh>
            <scale>1 1 1</scale>
            <uri>model://go2_description/dae/thigh.dae</uri>
          </mesh>
        </geometry>
        <material>
          <diffuse>0.839631855 0.86553216 0.967837751 1</diffuse>
          <ambient>0.839631855 0.86553216 0.967837751 1</ambient>
        </material>
      </visual>
    </link>
    <joint name='FL_calf_joint' type='revolute'>
      <pose relative_to='FL_thigh'>0 0 -0.21299999999999999 0 0 0</pose>
      <parent>FL_thigh</parent>
      <child>FL_calf</child>
      <axis>
        <xyz>0 1 0</xyz>
        <limit>
          <lower>-2.7227000000000001</lower>
          <upper>-0.83775999999999995</upper>
          <effort>45.43</effort>
          <velocity>15.699999999999999</velocity>
        </limit>
        <dynamics>
          <spring_reference>0</spring_reference>
          <spring_stiffness>0</spring_stiffness>
        </dynamics>
      </axis>
    </joint>
    <link name='FL_calf'>
      <pose relative_to='FL_calf_joint'>0 0 0 0 0 0</pose>
      <inertial>
        <pose>0.0043501030927835041 -0.00077396907216494828 -0.13520618556701031 0 0 0</pose>
        <mass>0.19400000000000001</mass>
        <inertia>
          <ixx>0.001394581937371134</ixx>
          <ixy>5.0965402061855686e-07</ixy>
          <ixz>1.4759587628868399e-07</ixz>
          <iyy>0.001415505295175258</iyy>
          <iyz>1.1313958762886591e-05</iyz>
          <izz>4.3483727391752568e-05</izz>
        </inertia>
      </inertial>
      <collision name='FL_calf_collision'>
        <pose>0.0080000000000000002 0 -0.059999999999999998 0 -0.20999999999999999 0</pose>
        <geometry>
          <cylinder>
            <length>0.12</length>
            <radius>0.012</radius>
          </cylinder>
        </geometry>
      </collision>
      <collision name='FL_calflower_collision_1'>
        <pose>0.02 0 -0.14799999999999999 0 0.050000000000000003 0</pose>
        <geometry>
          <cylinder>
            <length>0.065000000000000002</length>
            <radius>0.010999999999999999</radius>
          </cylinder>
        </geometry>
      </collision>
      <collision name='FL_calflower1_collision_2'>
        <pose>0.0080133306252232039 0 -0.18745021872309189 0 0.53000000000000014 0</pose>
        <geometry>
          <cylinder>
            <length>0.029999999999999999</length>
            <radius>0.0155</radius>
          </cylinder>
        </geometry>
      </collision>
      <collision name='FL_calf_fixed_joint_lump__FL_foot_collision_3'>
        <pose>-0.002 0 -0.21299999999999999 0 0 0</pose>
        <geometry>
          <sphere>
            <radius>0.021999999999999999</radius>
          </sphere>
        </geometry>
      </collision>
      <visual name='FL_calf_visual'>
        <pose>0 0 0 0 0 0</pose>
        <geometry>
          <mesh>
            <scale>1 1 1</scale>
            <uri>model://go2_description/dae/calf.dae</uri>
          </mesh>
        </geometry>
        <material>
          <diffuse>0 0 0 1</diffuse>
          <ambient>0 0 0 1</ambient>
        </material>
      </visual>
      <visual name='FL_calf_fixed_joint_lump__FL_foot_visual_1'>
        <pose>0 0 -0.21299999999999999 0 0 0</pose>
        <geometry>
          <mesh>
            <scale>1 1 1</scale>
            <uri>model://go2_description/dae/foot.dae</uri>
          </mesh>
        </geometry>
        <material>
          <diffuse>0 0 0 1</diffuse>
          <ambient>0 0 0 1</ambient>
        </material>
      </visual>
    </link>
    <joint name='FR_hip_joint' type='revolute'>
      <pose relative_to='base'>0.19339999999999999 -0.0465 0 0 0 0</pose>
      <parent>base</parent>
      <child>FR_hip</child>
      <axis>
        <xyz>1 0 0</xyz>
        <limit>
          <lower>-1.0471999999999999</lower>
          <upper>1.0471999999999999</upper>
          <effort>23.699999999999999</effort>
          <velocity>30.100000000000001</velocity>
        </limit>
        <dynamics>
          <spring_reference>0</spring_reference>
          <spring_stiffness>0</spring_stiffness>
        </dynamics>
      </axis>
    </joint>
    <link name='FR_hip'>
      <pose relative_to='FR_hip_joint'>0 0 0 0 0 0</pose>
      <inertial>
        <pose>-0.0047734028683181226 -0.00169748370273794 -9.2816166883963517e-05 0 0 0</pose>
        <mass>0.76700000000000002</mass>
        <inertia>
          <ixx>0.00053999151781062584</ixx>
          <ixy>2.1220993324641449e-06</ixy>
          <ixz>1.0653925501955671e-06</ixz>
          <iyy>0.00099813696478559337</iyy>
          <iyz>1.4027352647979141e-06</iyz>
          <izz>0.00065828474786205991</izz>
        </inertia>
      </inertial>
      <collision name='FR_hip_collision'>
        <pose>0 -0.080000000000000002 0 1.5707963267948959 0 0</pose>
        <geometry>
          <cylinder>
            <length>0.040000000000000001</length>
            <radius>0.045999999999999999</radius>
          </cylinder>
        </geometry>
      </collision>
      <visual name='FR_hip_visual'>
        <pose>0 0 0 3.1415000000000002 0 0</pose>
        <geometry>
          <mesh>
            <scale>1 1 1</scale>
            <uri>model://go2_description/dae/hip.dae</uri>
          </mesh>
        </geometry>
        <material>
          <diffuse>0.839631855 0.86553216 0.967837751 1</diffuse>
          <ambient>0.839631855 0.86553216 0.967837751 1</ambient>
        </material>
      </visual>
    </link>
    <joint name='FR_thigh_joint' type='revolute'>
      <pose relative_to='FR_hip'>0 -0.095500000000000002 0 0 0 0</pose>
      <parent>FR_hip</parent>
      <child>FR_thigh</child>
      <axis>
        <xyz>0 1 0</xyz>
        <limit>
          <lower>-1.5708</lower>
          <upper>3.4906999999999999</upper>
          <effort>23.699999999999999</effort>
          <velocity>30.100000000000001</velocity>
        </limit>
        <dynamics>
          <spring_reference>0</spring_reference>
          <spring_stiffness>0</spring_stiffness>
        </dynamics>
      </axis>
    </joint>
    <link name='FR_thigh'>
      <pose relative_to='FR_thigh_joint'>0 0 0 0 0 0</pose>
      <inertial>
        <pose>-0.003471780821917808 0.02302074939564867 -0.03035487510072523 0 0 0</pose>
        <mass>1.2410000000000001</mass>
        <inertia>
          <ixx>0.0059963333412087023</ixx>
          <ixy>-9.0305334356164388e-05</ixy>
          <ixz>-0.00029910392372602731</ixz>
          <iyy>0.0060013394099700237</iyy>
          <iyz>-0.00083515091803384382</iyz>
          <izz>0.0010991471651674461</izz>
        </inertia>
      </inertial>
      <collision name='FR_thigh_collision'>
        <pose>0 0 -0.1065 0 1.5707963267948966 0</pose>
        <geometry>
          <box>
            <size>0.21299999999999999 0.024500000000000001 0.034000000000000002</size>
          </box>
        </geometry>
      </collision>
      <visual name='FR_thigh_visual'>
        <pose>0 0 0 0 0 0</pose>
        <geometry>
          <mesh>
            <scale>1 1 1</scale>
            <uri>model://go2_description/dae/thigh_mirror.dae</uri>
          </mesh>
        </geometry>
        <material>
          <diffuse>0.839631855 0.86553216 0.967837751 1</diffuse>
          <ambient>0.839631855 0.86553216 0.967837751 1</ambient>
        </material>
      </visual>
    </link>
    <joint name='FR_calf_joint' type='revolute'>
      <pose relative_to='FR_thigh'>0 0 -0.21299999999999999 0 0 0</pose>
      <parent>FR_thigh</parent>
      <child>FR_calf</child>
      <axis>
        <xyz>0 1 0</xyz>
        <limit>
          <lower>-2.7227000000000001</lower>
          <upper>-0.83775999999999995</upper>
          <effort>45.43</effort>
          <velocity>15.699999999999999</velocity>
        </limit>
        <dynamics>
          <spring_reference>0</spring_reference>
          <spring_stiffness>0</spring_stiffness>
        </dynamics>
      </axis>
    </joint>
    <link name='FR_calf'>
      <pose relative_to='FR_calf_joint'>0 0 0 0 0 0</pose>
      <inertial>
        <pose>0.0043501030927835041 0.00077396907216494828 -0.13520618556701031 0 0 0</pose>
        <mass>0.19400000000000001</mass>
        <inertia>
          <ixx>0.001394581937371134</ixx>
          <ixy>-5.0965402061855686e-07</ixy>
          <ixz>1.4759587628868399e-07</ixz>
          <iyy>0.001415505295175258</iyy>
          <iyz>-1.1313958762886591e-05</iyz>
          <izz>4.3483727391752568e-05</izz>
        </inertia>
      </inertial>
      <collision name='FR_calf_collision'>
        <pose>0.01 0 -0.059999999999999998 0 -0.20000000000000004 0</pose>
        <geometry>
          <cylinder>
            <length>0.12</length>
            <radius>0.012999999999999999</radius>
          </cylinder>
        </geometry>
      </collision>
      <collision name='FR_calflower_collision_1'>
        <pose>0.02 0 -0.14799999999999999 0 0.050000000000000003 0</pose>
        <geometry>
          <cylinder>
            <length>0.065000000000000002</length>
            <radius>0.010999999999999999</radius>
          </cylinder>
        </geometry>
      </collision>
      <collision name='FR_calflower1_collision_2'>
        <pose>0.0080133306252232039 0 -0.18745021872309189 0 0.53000000000000014 0</pose>
        <geometry>
          <cylinder>
            <length>0.029999999999999999</length>
            <radius>0.0155</radius>
          </cylinder>
        </geometry>
      </collision>
      <collision name='FR_calf_fixed_joint_lump__FR_foot_collision_3'>
        <pose>-0.002 0 -0.21299999999999999 0 0 0</pose>
        <geometry>
          <sphere>
            <radius>0.021999999999999999</radius>
          </sphere>
        </geometry>
      </collision>
      <visual name='FR_calf_visual'>
        <pose>0 0 0 0 0 0</pose>
        <geometry>
          <mesh>
            <scale>1 1 1</scale>
            <uri>model://go2_description/dae/calf_mirror.dae</uri>
          </mesh>
        </geometry>
        <material>
          <diffuse>0 0 0 1</diffuse>
          <ambient>0 0 0 1</ambient>
        </material>
      </visual>
      <visual name='FR_calf_fixed_joint_lump__FR_foot_visual_1'>
        <pose>0 0 -0.21299999999999999 0 0 0</pose>
        <geometry>
          <mesh>
            <scale>1 1 1</scale>
            <uri>model://go2_description/dae/foot.dae</uri>
          </mesh>
        </geometry>
        <material>
          <diffuse>0 0 0 1</diffuse>
          <ambient>0 0 0 1</ambient>
        </material>
      </visual>
    </link>
    <joint name='RL_hip_joint' type='revolute'>
      <pose relative_to='base'>-0.19339999999999999 0.0465 0 0 0 0</pose>
      <parent>base</parent>
      <child>RL_hip</child>
      <axis>
        <xyz>1 0 0</xyz>
        <limit>
          <lower>-1.0471999999999999</lower>
          <upper>1.0471999999999999</upper>
          <effort>23.699999999999999</effort>
          <velocity>30.100000000000001</velocity>
        </limit>
        <dynamics>
          <spring_reference>0</spring_reference>
          <spring_stiffness>0</spring_stiffness>
        </dynamics>
      </axis>
    </joint>
    <link name='RL_hip'>
      <pose relative_to='RL_hip_joint'>0 0 0 0 0 0</pose>
      <inertial>
        <pose>0.0047734028683181226 0.00169748370273794 -9.2816166883963517e-05 0 0 0</pose>
        <mass>0.76700000000000002</mass>
        <inertia>
          <ixx>0.00053999151781062584</ixx>
          <ixy>2.1220993324641449e-06</ixy>
          <ixz>-1.0653925501955671e-06</ixz>
          <iyy>0.00099813696478559337</iyy>
          <iyz>-1.4027352647979141e-06</iyz>
          <izz>0.00065828474786205991</izz>
        </inertia>
      </inertial>
      <collision name='RL_hip_collision'>
        <pose>0 0.080000000000000002 0 1.5707963267948959 0 0</pose>
        <geometry>
          <cylinder>
            <length>0.040000000000000001</length>
            <radius>0.045999999999999999</radius>
          </cylinder>
        </geometry>
      </collision>
      <visual name='RL_hip_visual'>
        <pose>0 0 0 3.1415926535897931 9.265358979305727e-05 3.1415926535897931</pose>
        <geometry>
          <mesh>
            <scale>1 1 1</scale>
            <uri>model://go2_description/dae/hip.dae</uri>
          </mesh>
        </geometry>
        <material>
          <diffuse>0.839631855 0.86553216 0.967837751 1</diffuse>
          <ambient>0.839631855 0.86553216 0.967837751 1</ambient>
        </material>
      </visual>
    </link>
    <joint name='RL_thigh_joint' type='revolute'>
      <pose relative_to='RL_hip'>0 0.095500000000000002 0 0 0 0</pose>
      <parent>RL_hip</parent>
      <child>RL_thigh</child>
      <axis>
        <xyz>0 1 0</xyz>
        <limit>
          <lower>-0.52359999999999995</lower>
          <upper>4.5378999999999996</upper>
          <effort>23.699999999999999</effort>
          <velocity>30.100000000000001</velocity>
        </limit>
        <dynamics>
          <spring_reference>0</spring_reference>
          <spring_stiffness>0</spring_stiffness>
        </dynamics>
      </axis>
    </joint>
    <link name='RL_thigh'>
      <pose relative_to='RL_thigh_joint'>0 0 0 0 0 0</pose>
      <inertial>
        <pose>-0.003471780821917808 -0.02302074939564867 -0.03035487510072523 0 0 0</pose>
        <mass>1.2410000000000001</mass>
        <inertia>
          <ixx>0.0059963333412087023</ixx>
          <ixy>9.0305334356164388e-05</ixy>
          <ixz>-0.00029910392372602731</ixz>
          <iyy>0.0060013394099700237</iyy>
          <iyz>0.00083515091803384382</iyz>
          <izz>0.0010991471651674461</izz>
        </inertia>
      </inertial>
      <collision name='RL_thigh_collision'>
        <pose>0 0 -0.1065 0 1.5707963267948966 0</pose>
        <geometry>
          <box>
            <size>0.21299999999999999 0.024500000000000001 0.034000000000000002</size>
          </box>
        </geometry>
      </collision>
      <visual name='RL_thigh_visual'>
        <pose>0 0 0 0 0 0</pose>
        <geometry>
          <mesh>
            <scale>1 1 1</scale>
            <uri>model://go2_description/dae/thigh.dae</uri>
          </mesh>
        </geometry>
        <material>
          <diffuse>0.839631855 0.86553216 0.967837751 1</diffuse>
          <ambient>0.839631855 0.86553216 0.967837751 1</ambient>
        </material>
      </visual>
    </link>
    <joint name='RL_calf_joint' type='revolute'>
      <pose relative_to='RL_thigh'>0 0 -0.21299999999999999 0 0 0</pose>
      <parent>RL_thigh</parent>
      <child>RL_calf</child>
      <axis>
        <xyz>0 1 0</xyz>
        <limit>
          <lower>-2.7227000000000001</lower>
          <upper>-0.83775999999999995</upper>
          <effort>45.43</effort>
          <velocity>15.699999999999999</velocity>
        </limit>
        <dynamics>
          <spring_reference>0</spring_reference>
          <spring_stiffness>0</spring_stiffness>
        </dynamics>
      </axis>
    </joint>
    <link name='RL_calf'>
      <pose relative_to='RL_calf_joint'>0 0 0 0 0 0</pose>
      <inertial>
        <pose>0.0043501030927835041 -0.00077396907216494828 -0.13520618556701031 0 0 0</pose>
        <mass>0.19400000000000001</mass>
        <inertia>
          <ixx>0.001394581937371134</ixx>
          <ixy>5.0965402061855686e-07</ixy>
          <ixz>1.4759587628868399e-07</ixz>
          <iyy>0.001415505295175258</iyy>
          <iyz>1.1313958762886591e-05</iyz>
          <izz>4.3483727391752568e-05</izz>
        </inertia>
      </inertial>
      <collision name='RL_calf_collision'>
        <pose>0.01 0 -0.059999999999999998 0 -0.20000000000000004 0</pose>
        <geometry>
          <cylinder>
            <length>0.12</length>
            <radius>0.012999999999999999</radius>
          </cylinder>
        </geometry>
      </collision>
      <collision name='RL_calflower_collision_1'>
        <pose>0.02 0 -0.14799999999999999 0 0.050000000000000003 0</pose>
        <geometry>
          <cylinder>
            <length>0.065000000000000002</length>
            <radius>0.010999999999999999</radius>
          </cylinder>
        </geometry>
      </collision>
      <collision name='RL_calflower1_collision_2'>
        <pose>0.0080133306252232039 0 -0.18745021872309189 0 0.53000000000000014 0</pose>
        <geometry>
          <cylinder>
            <length>0.029999999999999999</length>
            <radius>0.0155</radius>
          </cylinder>
        </geometry>
      </collision>
      <collision name='RL_calf_fixed_joint_lump__RL_foot_collision_3'>
        <pose>-0.002 0 -0.21299999999999999 0 0 0</pose>
        <geometry>
          <sphere>
            <radius>0.021999999999999999</radius>
          </sphere>
        </geometry>
      </collision>
      <visual name='RL_calf_visual'>
        <pose>0 0 0 0 0 0</pose>
        <geometry>
          <mesh>
            <scale>1 1 1</scale>
            <uri>model://go2_description/dae/calf.dae</uri>
          </mesh>
        </geometry>
        <material>
          <diffuse>0 0 0 1</diffuse>
          <ambient>0 0 0 1</ambient>
        </material>
      </visual>
      <visual name='RL_calf_fixed_joint_lump__RL_foot_visual_1'>
        <pose>0 0 -0.21299999999999999 0 0 0</pose>
        <geometry>
          <mesh>
            <scale>1 1 1</scale>
            <uri>model://go2_description/dae/foot.dae</uri>
          </mesh>
        </geometry>
        <material>
          <diffuse>0 0 0 1</diffuse>
          <ambient>0 0 0 1</ambient>
        </material>
      </visual>
    </link>
    <joint name='RR_hip_joint' type='revolute'>
      <pose relative_to='base'>-0.19339999999999999 -0.0465 0 0 0 0</pose>
      <parent>base</parent>
      <child>RR_hip</child>
      <axis>
        <xyz>1 0 0</xyz>
        <limit>
          <lower>-1.0471999999999999</lower>
          <upper>1.0471999999999999</upper>
          <effort>23.699999999999999</effort>
          <velocity>30.100000000000001</velocity>
        </limit>
        <dynamics>
          <spring_reference>0</spring_reference>
          <spring_stiffness>0</spring_stiffness>
        </dynamics>
      </axis>
    </joint>
    <link name='RR_hip'>
      <pose relative_to='RR_hip_joint'>0 0 0 0 0 0</pose>
      <inertial>
        <pose>0.0047734028683181226 -0.00169748370273794 -9.2816166883963517e-05 0 0 0</pose>
        <mass>0.76700000000000002</mass>
        <inertia>
          <ixx>0.00053999151781062584</ixx>
          <ixy>-2.1220993324641449e-06</ixy>
          <ixz>-1.0653925501955671e-06</ixz>
          <iyy>0.00099813696478559337</iyy>
          <iyz>1.4027352647979141e-06</iyz>
          <izz>0.00065828474786205991</izz>
        </inertia>
      </inertial>
      <collision name='RR_hip_collision'>
        <pose>0 -0.080000000000000002 0 1.5707963267948959 0 0</pose>
        <geometry>
          <cylinder>
            <length>0.040000000000000001</length>
            <radius>0.045999999999999999</radius>
          </cylinder>
        </geometry>
      </collision>
      <visual name='RR_hip_visual'>
        <pose>0 0 0 -9.2653589793057257e-05 9.2653589793057284e-05 3.1415926535897931</pose>
        <geometry>
          <mesh>
            <scale>1 1 1</scale>
            <uri>model://go2_description/dae/hip.dae</uri>
          </mesh>
        </geometry>
        <material>
          <diffuse>0.839631855 0.86553216 0.967837751 1</diffuse>
          <ambient>0.839631855 0.86553216 0.967837751 1</ambient>
        </material>
      </visual>
    </link>
    <joint name='RR_thigh_joint' type='revolute'>
      <pose relative_to='RR_hip'>0 -0.095500000000000002 0 0 0 0</pose>
      <parent>RR_hip</parent>
      <child>RR_thigh</child>
      <axis>
        <xyz>0 1 0</xyz>
        <limit>
          <lower>-0.52359999999999995</lower>
          <upper>4.5378999999999996</upper>
          <effort>23.699999999999999</effort>
          <velocity>30.100000000000001</velocity>
        </limit>
        <dynamics>
          <spring_reference>0</spring_reference>
          <spring_stiffness>0</spring_stiffness>
        </dynamics>
      </axis>
    </joint>
    <link name='RR_thigh'>
      <pose relative_to='RR_thigh_joint'>0 0 0 0 0 0</pose>
      <inertial>
        <pose>-0.003471780821917808 0.02302074939564867 -0.03035487510072523 0 0 0</pose>
        <mass>1.2410000000000001</mass>
        <inertia>
          <ixx>0.0059963333412087023</ixx>
          <ixy>-9.0305334356164388e-05</ixy>
          <ixz>-0.00029910392372602731</ixz>
          <iyy>0.0060013394099700237</iyy>
          <iyz>-0.00083515091803384382</iyz>
          <izz>0.0010991471651674461</izz>
        </inertia>
      </inertial>
      <collision name='RR_thigh_collision'>
        <pose>0 0 -0.1065 0 1.5707963267948966 0</pose>
        <geometry>
          <box>
            <size>0.21299999999999999 0.024500000000000001 0.034000000000000002</size>
          </box>
        </geometry>
      </collision>
      <visual name='RR_thigh_visual'>
        <pose>0 0 0 0 0 0</pose>
        <geometry>
          <mesh>
            <scale>1 1 1</scale>
            <uri>model://go2_description/dae/thigh_mirror.dae</uri>
          </mesh>
        </geometry>
        <material>
          <diffuse>0.839631855 0.86553216 0.967837751 1</diffuse>
          <ambient>0.839631855 0.86553216 0.967837751 1</ambient>
        </material>
      </visual>
    </link>
    <joint name='RR_calf_joint' type='revolute'>
      <pose relative_to='RR_thigh'>0 0 -0.21299999999999999 0 0 0</pose>
      <parent>RR_thigh</parent>
      <child>RR_calf</child>
      <axis>
        <xyz>0 1 0</xyz>
        <limit>
          <lower>-2.7227000000000001</lower>
          <upper>-0.83775999999999995</upper>
          <effort>45.43</effort>
          <velocity>15.699999999999999</velocity>
        </limit>
        <dynamics>
          <spring_reference>0</spring_reference>
          <spring_stiffness>0</spring_stiffness>
        </dynamics>
      </axis>
    </joint>
    <link name='RR_calf'>
      <pose relative_to='RR_calf_joint'>0 0 0 0 0 0</pose>
      <inertial>
        <pose>0.0043501030927835041 0.00077396907216494828 -0.13520618556701031 0 0 0</pose>
        <mass>0.19400000000000001</mass>
        <inertia>
          <ixx>0.001394581937371134</ixx>
          <ixy>-5.0965402061855686e-07</ixy>
          <ixz>1.4759587628868399e-07</ixz>
          <iyy>0.001415505295175258</iyy>
          <iyz>-1.1313958762886591e-05</iyz>
          <izz>4.3483727391752568e-05</izz>
        </inertia>
      </inertial>
      <collision name='RR_calf_collision'>
        <pose>0.01 0 -0.059999999999999998 0 -0.20000000000000004 0</pose>
        <geometry>
          <cylinder>
            <length>0.12</length>
            <radius>0.012999999999999999</radius>
          </cylinder>
        </geometry>
      </collision>
      <collision name='RR_calflower_collision_1'>
        <pose>0.02 0 -0.14799999999999999 0 0.050000000000000003 0</pose>
        <geometry>
          <cylinder>
            <length>0.065000000000000002</length>
            <radius>0.010999999999999999</radius>
          </cylinder>
        </geometry>
      </collision>
      <collision name='RR_calflower1_collision_2'>
        <pose>0.0080133306252232039 0 -0.18745021872309189 0 0.53000000000000014 0</pose>
        <geometry>
          <cylinder>
            <length>0.029999999999999999</length>
            <radius>0.0155</radius>
          </cylinder>
        </geometry>
      </collision>
      <collision name='RR_calf_fixed_joint_lump__RR_foot_collision_3'>
        <pose>-0.002 0 -0.21299999999999999 0 0 0</pose>
        <geometry>
          <sphere>
            <radius>0.021999999999999999</radius>
          </sphere>
        </geometry>
      </collision>
      <visual name='RR_calf_visual'>
        <pose>0 0 0 0 0 0</pose>
        <geometry>
          <mesh>
            <scale>1 1 1</scale>
            <uri>model://go2_description/dae/calf_mirror.dae</uri>
          </mesh>
        </geometry>
        <material>
          <diffuse>0 0 0 1</diffuse>
          <ambient>0 0 0 1</ambient>
        </material>
      </visual>
      <visual name='RR_calf_fixed_joint_lump__RR_foot_visual_1'>
        <pose>0 0 -0.21299999999999999 0 0 0</pose>
        <geometry>
          <mesh>
            <scale>1 1 1</scale>
            <uri>model://go2_description/dae/foot.dae</uri>
          </mesh>
        </geometry>
        <material>
          <diffuse>0 0 0 1</diffuse>
          <ambient>0 0 0 1</ambient>
        </material>
      </visual>
    </link>
    <frame name='FL_hip_rotor_joint' attached_to='base'>
      <pose>0.11215 0.04675 0 0 0 0</pose>
    </frame>
    <frame name='FL_hip_rotor' attached_to='FL_hip_rotor_joint'>
      <pose>0 0 0 0 0 0</pose>
    </frame>
    <frame name='FR_hip_rotor_joint' attached_to='base'>
      <pose>0.11215 -0.04675 0 0 0 0</pose>
    </frame>
    <frame name='FR_hip_rotor' attached_to='FR_hip_rotor_joint'>
      <pose>0 0 0 0 0 0</pose>
    </frame>
    <frame name='Head_lower_joint' attached_to='Head_upper'>
      <pose>0.0080000000000000002 0 -0.070000000000000007 0 0 0</pose>
    </frame>
    <frame name='Head_lower' attached_to='Head_lower_joint'>
      <pose>0 0 0 0 0 0</pose>
    </frame>
    <frame name='Head_upper_joint' attached_to='base'>
      <pose>0.28499999999999998 0 0.01 0 0 0</pose>
    </frame>
    <frame name='Head_upper' attached_to='Head_upper_joint'>
      <pose>0 0 0 0 0 0</pose>
    </frame>
    <frame name='RL_hip_rotor_joint' attached_to='base'>
      <pose>-0.11215 0.04675 0 0 0 0</pose>
    </frame>
    <frame name='RL_hip_rotor' attached_to='RL_hip_rotor_joint'>
      <pose>0 0 0 0 0 0</pose>
    </frame>
    <frame name='RR_hip_rotor_joint' attached_to='base'>
      <pose>-0.11215 -0.04675 0 0 0 0</pose>
    </frame>
    <frame name='RR_hip_rotor' attached_to='RR_hip_rotor_joint'>
      <pose>0 0 0 0 0 0</pose>
    </frame>
    <frame name='front_camera_joint' attached_to='base'>
      <pose>0.32715 -3.0000000000000001e-05 0.042970000000000001 0 0 0</pose>
    </frame>
    <frame name='front_camera' attached_to='front_camera_joint'>
      <pose>0 0 0 0 0 0</pose>
    </frame>
    <frame name='imu_joint' attached_to='base'>
      <pose>-0.025569999999999999 0 0.042320000000000003 0 0 0</pose>
    </frame>
    <frame name='imu' attached_to='imu_joint'>
      <pose>0 0 0 0 0 0</pose>
    </frame>
    <frame name='radar_joint' attached_to='base'>
      <pose>0.28944999999999999 0 -0.046824999999999999 3.1415926535897931 0.26339265358979325 3.1415926535897931</pose>
    </frame>
    <frame name='radar' attached_to='radar_joint'>
      <pose>0 0 0 0 0 0</pose>
    </frame>
    <frame name='FL_thigh_rotor_joint' attached_to='FL_hip'>
      <pose>0 -0.00014999999999999999 0 0 0 0</pose>
    </frame>
    <frame name='FL_thigh_rotor' attached_to='FL_thigh_rotor_joint'>
      <pose>0 0 0 0 0 0</pose>
    </frame>
    <frame name='FL_calf_rotor_joint' attached_to='FL_thigh'>
      <pose>0 -0.032349999999999997 0 0 0 0</pose>
    </frame>
    <frame name='FL_calf_rotor' attached_to='FL_calf_rotor_joint'>
      <pose>0 0 0 0 0 0</pose>
    </frame>
    <frame name='FL_calflower1_joint' attached_to='FL_calflower'>
      <pose>-0.01 0 -0.040000000000000001 0 0.4800000000000002 0</pose>
    </frame>
    <frame name='FL_calflower1' attached_to='FL_calflower1_joint'>
      <pose>0 0 0 0 0 0</pose>
    </frame>
    <frame name='FL_calflower_joint' attached_to='FL_calf'>
      <pose>0.02 0 -0.14799999999999999 0 0.050000000000000003 0</pose>
    </frame>
    <frame name='FL_calflower' attached_to='FL_calflower_joint'>
      <pose>0 0 0 0 0 0</pose>
    </frame>
    <frame name='FL_foot_joint' attached_to='FL_calf'>
      <pose>0 0 -0.21299999999999999 0 0 0</pose>
    </frame>
    <frame name='FL_foot' attached_to='FL_foot_joint'>
      <pose>0 0 0 0 0 0</pose>
    </frame>
    <frame name='FR_thigh_rotor_joint' attached_to='FR_hip'>
      <pose>0 0.00014999999999999999 0 0 0 0</pose>
    </frame>
    <frame name='FR_thigh_rotor' attached_to='FR_thigh_rotor_joint'>
      <pose>0 0 0 0 0 0</pose>
    </frame>
    <frame name='FR_calf_rotor_joint' attached_to='FR_thigh'>
      <pose>0 0.032349999999999997 0 0 0 0</pose>
    </frame>
    <frame name='FR_calf_rotor' attached_to='FR_calf_rotor_joint'>
      <pose>0 0 0 0 0 0</pose>
    </frame>
    <frame name='FR_calflower1_joint' attached_to='FR_calflower'>
      <pose>-0.01 0 -0.040000000000000001 0 0.4800000000000002 0</pose>
    </frame>
    <frame name='FR_calflower1' attached_to='FR_calflower1_joint'>
      <pose>0 0 0 0 0 0</pose>
    </frame>
    <frame name='FR_calflower_joint' attached_to='FR_calf'>
      <pose>0.02 0 -0.14799999999999999 0 0.050000000000000003 0</pose>
    </frame>
    <frame name='FR_calflower' attached_to='FR_calflower_joint'>
      <pose>0 0 0 0 0 0</pose>
    </frame>
    <frame name='FR_foot_joint' attached_to='FR_calf'>
      <pose>0 0 -0.21299999999999999 0 0 0</pose>
    </frame>
    <frame name='FR_foot' attached_to='FR_foot_joint'>
      <pose>0 0 0 0 0 0</pose>
    </frame>
    <frame name='RL_thigh_rotor_joint' attached_to='RL_hip'>
      <pose>0 -0.00014999999999999999 0 0 0 0</pose>
    </frame>
    <frame name='RL_thigh_rotor' attached_to='RL_thigh_rotor_joint'>
      <pose>0 0 0 0 0 0</pose>
    </frame>
    <frame name='RL_calf_rotor_joint' attached_to='RL_thigh'>
      <pose>0 -0.032349999999999997 0 0 0 0</pose>
    </frame>
    <frame name='RL_calf_rotor' attached_to='RL_calf_rotor_joint'>
      <pose>0 0 0 0 0 0</pose>
    </frame>
    <frame name='RL_calflower1_joint' attached_to='RL_calflower'>
      <pose>-0.01 0 -0.040000000000000001 0 0.4800000000000002 0</pose>
    </frame>
    <frame name='RL_calflower1' attached_to='RL_calflower1_joint'>
      <pose>0 0 0 0 0 0</pose>
    </frame>
    <frame name='RL_calflower_joint' attached_to='RL_calf'>
      <pose>0.02 0 -0.14799999999999999 0 0.050000000000000003 0</pose>
    </frame>
    <frame name='RL_calflower' attached_to='RL_calflower_joint'>
      <pose>0 0 0 0 0 0</pose>
    </frame>
    <frame name='RL_foot_joint' attached_to='RL_calf'>
      <pose>0 0 -0.21299999999999999 0 0 0</pose>
    </frame>
    <frame name='RL_foot' attached_to='RL_foot_joint'>
      <pose>0 0 0 0 0 0</pose>
    </frame>
    <frame name='RR_thigh_rotor_joint' attached_to='RR_hip'>
      <pose>0 0.00014999999999999999 0 0 0 0</pose>
    </frame>
    <frame name='RR_thigh_rotor' attached_to='RR_thigh_rotor_joint'>
      <pose>0 0 0 0 0 0</pose>
    </frame>
    <frame name='RR_calf_rotor_joint' attached_to='RR_thigh'>
      <pose>0 0.032349999999999997 0 0 0 0</pose>
    </frame>
    <frame name='RR_calf_rotor' attached_to='RR_calf_rotor_joint'>
      <pose>0 0 0 0 0 0</pose>
    </frame>
    <frame name='RR_calflower1_joint' attached_to='RR_calflower'>
      <pose>-0.01 0 -0.040000000000000001 0 0.4800000000000002 0</pose>
    </frame>
    <frame name='RR_calflower1' attached_to='RR_calflower1_joint'>
      <pose>0 0 0 0 0 0</pose>
    </frame>
    <frame name='RR_calflower_joint' attached_to='RR_calf'>
      <pose>0.02 0 -0.14799999999999999 0 0.050000000000000003 0</pose>
    </frame>
    <frame name='RR_calflower' attached_to='RR_calflower_joint'>
      <pose>0 0 0 0 0 0</pose>
    </frame>
    <frame name='RR_foot_joint' attached_to='RR_calf'>
      <pose>0 0 -0.21299999999999999 0 0 0</pose>
    </frame>
    <frame name='RR_foot' attached_to='RR_foot_joint'>
      <pose>0 0 0 0 0 0</pose>
    </frame>
  
    <plugin filename="gz-sim-apply-joint-force-system" name="gz::sim::systems::ApplyJointForce">
      <joint_name>FL_hip_joint</joint_name>
    </plugin>
    <plugin filename="gz-sim-apply-joint-force-system" name="gz::sim::systems::ApplyJointForce">
      <joint_name>FR_hip_joint</joint_name>
    </plugin>
    <plugin filename="gz-sim-apply-joint-force-system" name="gz::sim::systems::ApplyJointForce">
      <joint_name>RL_hip_joint</joint_name>
    </plugin>
    <plugin filename="gz-sim-apply-joint-force-system" name="gz::sim::systems::ApplyJointForce">
      <joint_name>RR_hip_joint</joint_name>
    </plugin>
    <plugin filename="gz-sim-apply-joint-force-system" name="gz::sim::systems::ApplyJointForce">
      <joint_name>FL_thigh_joint</joint_name>
    </plugin>
    <plugin filename="gz-sim-apply-joint-force-system" name="gz::sim::systems::ApplyJointForce">
      <joint_name>FR_thigh_joint</joint_name>
    </plugin>
    <plugin filename="gz-sim-apply-joint-force-system" name="gz::sim::systems::ApplyJointForce">
      <joint_name>RL_thigh_joint</joint_name>
    </plugin>
    <plugin filename="gz-sim-apply-joint-force-system" name="gz::sim::systems::ApplyJointForce">
      <joint_name>RR_thigh_joint</joint_name>
    </plugin>
    <plugin filename="gz-sim-apply-joint-force-system" name="gz::sim::systems::ApplyJointForce">
      <joint_name>FL_calf_joint</joint_name>
    </plugin>
    <plugin filename="gz-sim-apply-joint-force-system" name="gz::sim::systems::ApplyJointForce">
      <joint_name>FR_calf_joint</joint_name>
    </plugin>
    <plugin filename="gz-sim-apply-joint-force-system" name="gz::sim::systems::ApplyJointForce">
      <joint_name>RL_calf_joint</joint_name>
    </plugin>
    <plugin filename="gz-sim-apply-joint-force-system" name="gz::sim::systems::ApplyJointForce">
      <joint_name>RR_calf_joint</joint_name>
    </plugin>
    <plugin filename="gz-sim-joint-state-publisher-system" name="gz::sim::systems::JointStatePublisher">
        <topic>/model/go2/joint_state</topic>
        <update_frequency>200</update_frequency>
        <joint_name>FL_hip_joint</joint_name>
        <joint_name>FR_hip_joint</joint_name>
        <joint_name>RL_hip_joint</joint_name>
        <joint_name>RR_hip_joint</joint_name>
        <joint_name>FL_thigh_joint</joint_name>
        <joint_name>FR_thigh_joint</joint_name>
        <joint_name>RL_thigh_joint</joint_name>
        <joint_name>RR_thigh_joint</joint_name>
        <joint_name>FL_calf_joint</joint_name>
        <joint_name>FR_calf_joint</joint_name>
        <joint_name>RL_calf_joint</joint_name>
        <joint_name>RR_calf_joint</joint_name>
    </plugin>
    <plugin filename="gz-sim-odometry-publisher-system" name="gz::sim::systems::OdometryPublisher">
      <odom_frame>odom</odom_frame>
      <robot_base_frame>base</robot_base_frame>
      <odom_publish_frequency>200</odom_publish_frequency>
      <dimensions>3</dimensions>
    </plugin>
    <plugin filename="gz-sim-pose-publisher-system" name="gz::sim::systems::PosePublisher">
      <publish_link_pose>false</publish_link_pose>
      <use_sensor_names>true</use_sensor_names>
      <publish_collision_pose>false</publish_collision_pose>
      <publish_visual_pose>false</publish_visual_pose>
      <publish_nested_model_pose>true</publish_nested_model_pose>
      <update_frequency>50</update_frequency>
    </plugin>
  </model>
</sdf>
