<mujoco model="go2">
  <compiler angle="radian" meshdir="assets" autolimits="true"/>

  <option cone="elliptic" impratio="100"/>

  <default>
    <default class="go2/go2">
      <geom friction="0.6" margin="0.001" condim="1"/>
      <joint axis="0 1 0" damping="2" armature="0.01" frictionloss="0.2"/>
      <motor ctrlrange="-23.7 23.7"/>
      <default class="go2/abduction">
        <joint axis="1 0 0" range="-1.0472 1.0472"/>
      </default>
      <default class="go2/hip">
        <default class="go2/front_hip">
          <joint range="-1.5708 3.4907"/>
        </default>
        <default class="go2/back_hip">
          <joint range="-0.5236 4.5379"/>
        </default>
      </default>
      <default class="go2/knee">
        <joint range="-2.7227 -0.83776"/>
        <motor ctrlrange="-45.43 45.43"/>
      </default>
      <default class="go2/visual">
        <geom type="mesh" contype="0" conaffinity="0" group="2"/>
      </default>
      <default class="go2/collision">
        <geom group="3"/>
        <default class="go2/foot">
          <geom size="0.022" pos="-0.002 0 -0.213" priority="1" solimp="0.015 1 0.022" condim="6"
            friction="0.8 0.02 0.01"/>
        </default>
      </default>
    </default>
  </default>

  <asset>
    <material name="metal" rgba=".9 .95 .95 1"/>
    <material name="black" rgba="0 0 0 1"/>
    <material name="white" rgba="1 1 1 1"/>
    <material name="gray" rgba="0.671705 0.692426 0.774270 1"/>

    <mesh file="base_0.obj"/>
    <mesh file="base_1.obj"/>
    <mesh file="base_2.obj"/>
    <mesh file="base_3.obj"/>
    <mesh file="base_4.obj"/>
    <mesh file="hip_0.obj"/>
    <mesh file="hip_1.obj"/>
    <mesh file="thigh_0.obj"/>
    <mesh file="thigh_1.obj"/>
    <mesh file="thigh_mirror_0.obj"/>
    <mesh file="thigh_mirror_1.obj"/>
    <mesh file="calf_0.obj"/>
    <mesh file="calf_1.obj"/>
    <mesh file="calf_mirror_0.obj"/>
    <mesh file="calf_mirror_1.obj"/>
    <mesh file="foot.obj"/>
  </asset>

  <worldbody>
    <body name="base" pos="0 0 0.445" childclass="go2/go2/go2">
      <inertial pos="0.021112 0 -0.005366" quat="-0.000543471 0.713435 -0.00173769 0.700719" mass="6.921"
        diaginertia="0.107027 0.0980771 0.0244531"/>
      <freejoint/>
      <geom mesh="go2/base_0" material="go2/black" class="go2/visual"/>
      <geom mesh="go2/base_1" material="go2/black" class="go2/visual"/>
      <geom mesh="go2/base_2" material="go2/black" class="go2/visual"/>
      <geom mesh="go2/base_3" material="go2/white" class="go2/visual"/>
      <geom mesh="go2/base_4" material="go2/gray" class="go2/visual"/>
      <geom size="0.1881 0.04675 0.057" type="box" class="go2/collision"/>
      <geom size="0.05 0.045" pos="0.285 0 0.01" type="cylinder" class="go2/collision"/>
      <geom size="0.047" pos="0.293 0 -0.06" class="go2/collision"/>
      <site name="imu" pos="-0.02557 0 0.04232"/>
      <body name="FL_hip" pos="0.1934 0.0465 0">
        <inertial pos="-0.0054 0.00194 -0.000105" quat="0.497014 0.499245 0.505462 0.498237" mass="0.678"
          diaginertia="0.00088403 0.000596003 0.000479967"/>
        <joint name="FL_hip_joint" class="go2/abduction"/>
        <geom mesh="go2/hip_0" material="go2/metal" class="go2/visual"/>
        <geom mesh="go2/hip_1" material="go2/gray" class="go2/visual"/>
        <geom size="0.046 0.02" pos="0 0.08 0" quat="1 1 0 0" type="cylinder" class="go2/collision"/>
        <body name="FL_thigh" pos="0 0.0955 0">
          <inertial pos="-0.00374 -0.0223 -0.0327" quat="0.829533 0.0847635 -0.0200632 0.551623" mass="1.152"
            diaginertia="0.00594973 0.00584149 0.000878787"/>
          <joint name="FL_thigh_joint" class="go2/front_hip"/>
          <geom mesh="go2/thigh_0" material="go2/metal" class="go2/visual"/>
          <geom mesh="go2/thigh_1" material="go2/gray" class="go2/visual"/>
          <geom size="0.1065 0.01225 0.017" pos="0 0 -0.1065" quat="0.707107 0 0.707107 0" type="box" class="go2/collision"/>
          <body name="FL_calf" pos="0 0 -0.213">
            <inertial pos="0.00629595 -0.000622121 -0.141417" quat="0.710672 0.00154099 -0.00450087 0.703508"
              mass="0.241352" diaginertia="0.0014901 0.00146356 5.31397e-05"/>
            <joint name="FL_calf_joint" class="go2/knee"/>
            <geom mesh="go2/calf_0" material="go2/gray" class="go2/visual"/>
            <geom mesh="go2/calf_1" material="go2/black" class="go2/visual"/>
            <geom size="0.012 0.06" pos="0.008 0 -0.06" quat="0.994493 0 -0.104807 0" type="cylinder" class="go2/collision"/>
            <geom size="0.011 0.0325" pos="0.02 0 -0.148" quat="0.999688 0 0.0249974 0" type="cylinder" class="go2/collision"/>
            <geom pos="0 0 -0.213" mesh="go2/foot" class="go2/visual" material="go2/black"/>
            <geom name="FL" class="go2/foot"/>
          </body>
        </body>
      </body>
      <body name="FR_hip" pos="0.1934 -0.0465 0">
        <inertial pos="-0.0054 -0.00194 -0.000105" quat="0.498237 0.505462 0.499245 0.497014" mass="0.678"
          diaginertia="0.00088403 0.000596003 0.000479967"/>
        <joint name="FR_hip_joint" class="go2/abduction"/>
        <geom mesh="go2/hip_0" material="go2/metal" class="go2/visual" quat="4.63268e-05 1 0 0"/>
        <geom mesh="go2/hip_1" material="go2/gray" class="go2/visual" quat="4.63268e-05 1 0 0"/>
        <geom size="0.046 0.02" pos="0 -0.08 0" quat="0.707107 0.707107 0 0" type="cylinder" class="go2/collision"/>
        <body name="FR_thigh" pos="0 -0.0955 0">
          <inertial pos="-0.00374 0.0223 -0.0327" quat="0.551623 -0.0200632 0.0847635 0.829533" mass="1.152"
            diaginertia="0.00594973 0.00584149 0.000878787"/>
          <joint name="FR_thigh_joint" class="go2/front_hip"/>
          <geom mesh="go2/thigh_mirror_0" material="go2/metal" class="go2/visual"/>
          <geom mesh="go2/thigh_mirror_1" material="go2/gray" class="go2/visual"/>
          <geom size="0.1065 0.01225 0.017" pos="0 0 -0.1065" quat="0.707107 0 0.707107 0" type="box" class="go2/collision"/>
          <body name="FR_calf" pos="0 0 -0.213">
            <inertial pos="0.00629595 0.000622121 -0.141417" quat="0.703508 -0.00450087 0.00154099 0.710672"
              mass="0.241352" diaginertia="0.0014901 0.00146356 5.31397e-05"/>
            <joint name="FR_calf_joint" class="go2/knee"/>
            <geom mesh="go2/calf_mirror_0" material="go2/gray" class="go2/visual"/>
            <geom mesh="go2/calf_mirror_1" material="go2/black" class="go2/visual"/>
            <geom size="0.013 0.06" pos="0.01 0 -0.06" quat="0.995004 0 -0.0998334 0" type="cylinder" class="go2/collision"/>
            <geom size="0.011 0.0325" pos="0.02 0 -0.148" quat="0.999688 0 0.0249974 0" type="cylinder" class="go2/collision"/>
            <geom pos="0 0 -0.213" mesh="go2/foot" class="go2/visual" material="go2/black"/>
            <geom name="FR" class="go2/foot"/>
          </body>
        </body>
      </body>
      <body name="RL_hip" pos="-0.1934 0.0465 0">
        <inertial pos="0.0054 0.00194 -0.000105" quat="0.505462 0.498237 0.497014 0.499245" mass="0.678"
          diaginertia="0.00088403 0.000596003 0.000479967"/>
        <joint name="RL_hip_joint" class="go2/abduction"/>
        <geom mesh="go2/hip_0" material="go2/metal" class="go2/visual" quat="4.63268e-05 0 1 0"/>
        <geom mesh="go2/hip_1" material="go2/gray" class="go2/visual" quat="4.63268e-05 0 1 0"/>
        <geom size="0.046 0.02" pos="0 0.08 0" quat="0.707107 0.707107 0 0" type="cylinder" class="go2/collision"/>
        <body name="RL_thigh" pos="0 0.0955 0">
          <inertial pos="-0.00374 -0.0223 -0.0327" quat="0.829533 0.0847635 -0.0200632 0.551623" mass="1.152"
            diaginertia="0.00594973 0.00584149 0.000878787"/>
          <joint name="RL_thigh_joint" class="go2/back_hip"/>
          <geom mesh="go2/thigh_0" material="go2/metal" class="go2/visual"/>
          <geom mesh="go2/thigh_1" material="go2/gray" class="go2/visual"/>
          <geom size="0.1065 0.01225 0.017" pos="0 0 -0.1065" quat="0.707107 0 0.707107 0" type="box" class="go2/collision"/>
          <body name="RL_calf" pos="0 0 -0.213">
            <inertial pos="0.00629595 -0.000622121 -0.141417" quat="0.710672 0.00154099 -0.00450087 0.703508"
              mass="0.241352" diaginertia="0.0014901 0.00146356 5.31397e-05"/>
            <joint name="RL_calf_joint" class="go2/knee"/>
            <geom mesh="go2/calf_0" material="go2/gray" class="go2/visual"/>
            <geom mesh="go2/calf_1" material="go2/black" class="go2/visual"/>
            <geom size="0.013 0.06" pos="0.01 0 -0.06" quat="0.995004 0 -0.0998334 0" type="cylinder" class="go2/collision"/>
            <geom size="0.011 0.0325" pos="0.02 0 -0.148" quat="0.999688 0 0.0249974 0" type="cylinder" class="go2/collision"/>
            <geom pos="0 0 -0.213" mesh="go2/foot" class="go2/visual" material="go2/black"/>
            <geom name="RL" class="go2/foot"/>
          </body>
        </body>
      </body>
      <body name="RR_hip" pos="-0.1934 -0.0465 0">
        <inertial pos="0.0054 -0.00194 -0.000105" quat="0.499245 0.497014 0.498237 0.505462" mass="0.678"
          diaginertia="0.00088403 0.000596003 0.000479967"/>
        <joint name="RR_hip_joint" class="go2/abduction"/>
        <geom mesh="go2/hip_0" material="go2/metal" class="go2/visual" quat="2.14617e-09 4.63268e-05 4.63268e-05 -1"/>
        <geom mesh="go2/hip_1" material="go2/gray" class="go2/visual" quat="2.14617e-09 4.63268e-05 4.63268e-05 -1"/>
        <geom size="0.046 0.02" pos="0 -0.08 0" quat="0.707107 0.707107 0 0" type="cylinder" class="go2/collision"/>
        <body name="RR_thigh" pos="0 -0.0955 0">
          <inertial pos="-0.00374 0.0223 -0.0327" quat="0.551623 -0.0200632 0.0847635 0.829533" mass="1.152"
            diaginertia="0.00594973 0.00584149 0.000878787"/>
          <joint name="RR_thigh_joint" class="go2/back_hip"/>
          <geom mesh="go2/thigh_mirror_0" material="go2/metal" class="go2/visual"/>
          <geom mesh="go2/thigh_mirror_1" material="go2/gray" class="go2/visual"/>
          <geom size="0.1065 0.01225 0.017" pos="0 0 -0.1065" quat="0.707107 0 0.707107 0" type="box" class="go2/collision"/>
          <body name="RR_calf" pos="0 0 -0.213">
            <inertial pos="0.00629595 0.000622121 -0.141417" quat="0.703508 -0.00450087 0.00154099 0.710672"
              mass="0.241352" diaginertia="0.0014901 0.00146356 5.31397e-05"/>
            <joint name="RR_calf_joint" class="go2/knee"/>
            <geom mesh="go2/calf_mirror_0" material="go2/gray" class="go2/visual"/>
            <geom mesh="go2/calf_mirror_1" material="go2/black" class="go2/visual"/>
            <geom size="0.013 0.06" pos="0.01 0 -0.06" quat="0.995004 0 -0.0998334 0" type="cylinder" class="go2/collision"/>
            <geom size="0.011 0.0325" pos="0.02 0 -0.148" quat="0.999688 0 0.0249974 0" type="cylinder" class="go2/collision"/>
            <geom pos="0 0 -0.213" mesh="go2/foot" class="go2/visual" material="go2/black"/>
            <geom name="RR" class="go2/foot"/>
          </body>
        </body>
      </body>
    </body>
  </worldbody>

  <actuator>
    <motor class="go2/abduction" name="FL_hip" joint="FL_hip_joint"/>
    <motor class="go2/hip" name="FL_thigh" joint="FL_thigh_joint"/>
    <motor class="go2/knee" name="FL_calf" joint="FL_calf_joint"/>
    <motor class="go2/abduction" name="FR_hip" joint="FR_hip_joint"/>
    <motor class="go2/hip" name="FR_thigh" joint="FR_thigh_joint"/>
    <motor class="go2/knee" name="FR_calf" joint="FR_calf_joint"/>
    <motor class="go2/abduction" name="RL_hip" joint="RL_hip_joint"/>
    <motor class="go2/hip" name="RL_thigh" joint="RL_thigh_joint"/>
    <motor class="go2/knee" name="RL_calf" joint="RL_calf_joint"/>
    <motor class="go2/abduction" name="RR_hip" joint="RR_hip_joint"/>
    <motor class="go2/hip" name="RR_thigh" joint="RR_thigh_joint"/>
    <motor class="go2/knee" name="RR_calf" joint="RR_calf_joint"/>
  </actuator>

  <keyframe>
    <key name="home" qpos="0 0 0.27 1 0 0 0 0 0.9 -1.8 0 0.9 -1.8 0 0.9 -1.8 0 0.9 -1.8"
      ctrl="0 0.9 -1.8 0 0.9 -1.8 0 0.9 -1.8 0 0.9 -1.8"/>
  </keyframe>
</mujoco>
