<sdf version='1.11'>
  <model name='go2'>
    <link name='base'>
      <inertial>
        <pose>0.020866157113366479 0.001859672042121315 -0.00046917899041193432 0 0 0</pose>
        <mass>5.5610799999999987</mass>
        <inertia>
          <ixx>0.018152741714880381</ixx>
          <ixy>-0.00024707762715734321</ixy>
          <ixz>-0.00029100362356646752</ixz>
          <iyy>0.068003178569477754</iyy>
          <iyz>-4.1923289795357292e-05</iyz>
          <izz>0.077432530599337079</izz>
        </inertia>
      </inertial>
      <collision name='base_fixed_joint_lump__trunk_collision'>
        <pose>0 0 0 0 0 0</pose>
        <geometry>
          <box>
            <size>0.37619999999999998 0.0935 0.114</size>
          </box>
        </geometry>
      </collision>
      <collision name='base_fixed_joint_lump__camera_chin_collision_1'>
        <pose>0.25219999999999998 0.012500000000000001 -0.0436 3.1415926535897931 1.5707963267948966 0</pose>
        <geometry>
          <box>
            <size>0.001 0.001 0.001</size>
          </box>
        </geometry>
      </collision>
      <collision name='base_fixed_joint_lump__camera_face_collision_2'>
        <pose>0.27850000000000003 0.012500000000000001 0.0167 3.1415926535897931 0 0</pose>
        <geometry>
          <box>
            <size>0.001 0.001 0.001</size>
          </box>
        </geometry>
      </collision>
      <collision name='base_fixed_joint_lump__camera_left_collision_3'>
        <pose>-0.066000000000000003 0.082000000000000003 -0.017600000000000001 3.1415926535897931 0.26179999999999998 1.5707963267948957</pose>
        <geometry>
          <box>
            <size>0.001 0.001 0.001</size>
          </box>
        </geometry>
      </collision>
      <collision name='base_fixed_joint_lump__camera_rearDown_collision_4'>
        <pose>-0.082500000000000004 0.012500000000000001 -0.043650000000000001 3.1415926535897931 1.5707963267948966 0</pose>
        <geometry>
          <box>
            <size>0.001 0.001 0.001</size>
          </box>
        </geometry>
      </collision>
      <collision name='base_fixed_joint_lump__camera_right_collision_5'>
        <pose>-0.041000000000000002 -0.082000000000000003 -0.017600000000000001 3.1415926535897931 0.26179999999999998 -1.570796326794897</pose>
        <geometry>
          <box>
            <size>0.001 0.001 0.001</size>
          </box>
        </geometry>
      </collision>
      <collision name='base_fixed_joint_lump__imu_link_collision_6'>
        <pose>-0.01592 -0.066589999999999996 -0.0061700000000000001 0 0 0</pose>
        <geometry>
          <box>
            <size>0.001 0.001 0.001</size>
          </box>
        </geometry>
      </collision>
      <collision name='base_fixed_joint_lump__lf_hipassembly_rotor_collision_7'>
        <pose>0.11215 0.04675 0 0 1.5707963267948966 0</pose>
        <geometry>
          <cylinder>
            <length>0.02</length>
            <radius>0.035000000000000003</radius>
          </cylinder>
        </geometry>
      </collision>
      <collision name='base_fixed_joint_lump__lh_hipassembly_rotor_collision_8'>
        <pose>-0.11215 0.04675 0 0 1.5707963267948966 0</pose>
        <geometry>
          <cylinder>
            <length>0.02</length>
            <radius>0.035000000000000003</radius>
          </cylinder>
        </geometry>
      </collision>
      <collision name='base_fixed_joint_lump__rf_hipassembly_rotor_collision_9'>
        <pose>0.11215 -0.04675 0 0 1.5707963267948966 0</pose>
        <geometry>
          <cylinder>
            <length>0.02</length>
            <radius>0.035000000000000003</radius>
          </cylinder>
        </geometry>
      </collision>
      <collision name='base_fixed_joint_lump__rh_hipassembly_rotor_collision_10'>
        <pose>-0.11215 -0.04675 0 0 1.5707963267948966 0</pose>
        <geometry>
          <cylinder>
            <length>0.02</length>
            <radius>0.035000000000000003</radius>
          </cylinder>
        </geometry>
      </collision>
      <collision name='base_fixed_joint_lump__ultraSound_face_collision_11'>
        <pose>0.2747 0 -0.0088000000000000005 0 0 0</pose>
        <geometry>
          <box>
            <size>0.001 0.001 0.001</size>
          </box>
        </geometry>
      </collision>
      <collision name='base_fixed_joint_lump__ultraSound_left_collision_12'>
        <pose>-0.053499999999999999 0.082600000000000007 0.0086800000000000002 0 0.26179999999999998 1.570796326794897</pose>
        <geometry>
          <box>
            <size>0.001 0.001 0.001</size>
          </box>
        </geometry>
      </collision>
      <collision name='base_fixed_joint_lump__ultraSound_right_collision_13'>
        <pose>-0.053499999999999999 -0.082600000000000007 0.0086800000000000002 0 0.26179999999999998 -1.570796326794897</pose>
        <geometry>
          <box>
            <size>0.001 0.001 0.001</size>
          </box>
        </geometry>
      </collision>
      <visual name='base_visual'>
        <pose>0 0 0 0 0 0</pose>
        <geometry>
          <box>
            <size>0.001 0.001 0.001</size>
          </box>
        </geometry>
      </visual>
      <visual name='base_fixed_joint_lump__trunk_visual_1'>
        <pose>0 0 0 0 0 0</pose>
        <geometry>
          <mesh>
            <scale>1 1 1</scale>
            <uri>models/unitree_go2/meshes/trunk/trunk.dae</uri>
          </mesh>
        </geometry>
      </visual>
      <visual name='base_fixed_joint_lump__camera_chin_visual_2'>
        <pose>0.25219999999999998 0.012500000000000001 -0.0436 3.1415926535897931 1.5707963267948966 0</pose>
        <geometry>
          <mesh>
            <scale>1 1 1</scale>
            <uri>models/unitree_go2/meshes/depthCamera.dae</uri>
          </mesh>
        </geometry>
      </visual>
      <visual name='base_fixed_joint_lump__camera_face_visual_3'>
        <pose>0.27850000000000003 0.012500000000000001 0.0167 3.1415926535897931 0 0</pose>
        <geometry>
          <mesh>
            <scale>1 1 1</scale>
            <uri>models/unitree_go2/meshes/depthCamera.dae</uri>
          </mesh>
        </geometry>
      </visual>
      <visual name='base_fixed_joint_lump__camera_left_visual_4'>
        <pose>-0.066000000000000003 0.082000000000000003 -0.017600000000000001 3.1415926535897931 0.26179999999999998 1.5707963267948957</pose>
        <geometry>
          <mesh>
            <scale>1 1 1</scale>
            <uri>models/unitree_go2/meshes/depthCamera.dae</uri>
          </mesh>
        </geometry>
      </visual>
      <visual name='base_fixed_joint_lump__camera_rearDown_visual_5'>
        <pose>-0.082500000000000004 0.012500000000000001 -0.043650000000000001 3.1415926535897931 1.5707963267948966 0</pose>
        <geometry>
          <mesh>
            <scale>1 1 1</scale>
            <uri>models/unitree_go2/meshes/depthCamera.dae</uri>
          </mesh>
        </geometry>
      </visual>
      <visual name='base_fixed_joint_lump__camera_right_visual_6'>
        <pose>-0.041000000000000002 -0.082000000000000003 -0.017600000000000001 3.1415926535897931 0.26179999999999998 -1.570796326794897</pose>
        <geometry>
          <mesh>
            <scale>1 1 1</scale>
            <uri>models/unitree_go2/meshes/depthCamera.dae</uri>
          </mesh>
        </geometry>
      </visual>
      <visual name='base_fixed_joint_lump__imu_link_visual_7'>
        <pose>-0.01592 -0.066589999999999996 -0.0061700000000000001 0 0 0</pose>
        <geometry>
          <box>
            <size>0.001 0.001 0.001</size>
          </box>
        </geometry>
      </visual>
      <visual name='base_fixed_joint_lump__lf_hipassembly_rotor_visual_8'>
        <pose>0.11215 0.04675 0 0 1.5707963267948966 0</pose>
        <geometry>
          <cylinder>
            <length>0.02</length>
            <radius>0.035000000000000003</radius>
          </cylinder>
        </geometry>
        <material>
          <diffuse>0 1 0 1</diffuse>
          <ambient>0 1 0 1</ambient>
        </material>
      </visual>
      <visual name='base_fixed_joint_lump__lh_hipassembly_rotor_visual_9'>
        <pose>-0.11215 0.04675 0 0 1.5707963267948966 0</pose>
        <geometry>
          <cylinder>
            <length>0.02</length>
            <radius>0.035000000000000003</radius>
          </cylinder>
        </geometry>
        <material>
          <diffuse>0 1 0 1</diffuse>
          <ambient>0 1 0 1</ambient>
        </material>
      </visual>
      <visual name='base_fixed_joint_lump__rf_hipassembly_rotor_visual_10'>
        <pose>0.11215 -0.04675 0 0 1.5707963267948966 0</pose>
        <geometry>
          <cylinder>
            <length>0.02</length>
            <radius>0.035000000000000003</radius>
          </cylinder>
        </geometry>
        <material>
          <diffuse>0 1 0 1</diffuse>
          <ambient>0 1 0 1</ambient>
        </material>
      </visual>
      <visual name='base_fixed_joint_lump__rh_hipassembly_rotor_visual_11'>
        <pose>-0.11215 -0.04675 0 0 1.5707963267948966 0</pose>
        <geometry>
          <cylinder>
            <length>0.02</length>
            <radius>0.035000000000000003</radius>
          </cylinder>
        </geometry>
        <material>
          <diffuse>0 1 0 1</diffuse>
          <ambient>0 1 0 1</ambient>
        </material>
      </visual>
      <visual name='base_fixed_joint_lump__ultraSound_face_visual_12'>
        <pose>0.2747 0 -0.0088000000000000005 0 0 0</pose>
        <geometry>
          <mesh>
            <scale>1 1 1</scale>
            <uri>models/unitree_go2/meshes/ultraSound.dae</uri>
          </mesh>
        </geometry>
        <material>
          <diffuse>0 0 0 1</diffuse>
          <ambient>0 0 0 1</ambient>
        </material>
      </visual>
      <visual name='base_fixed_joint_lump__ultraSound_left_visual_13'>
        <pose>-0.053499999999999999 0.082600000000000007 0.0086800000000000002 0 0.26179999999999998 1.570796326794897</pose>
        <geometry>
          <mesh>
            <scale>1 1 1</scale>
            <uri>models/unitree_go2/meshes/ultraSound.dae</uri>
          </mesh>
        </geometry>
        <material>
          <diffuse>0 0 0 1</diffuse>
          <ambient>0 0 0 1</ambient>
        </material>
      </visual>
      <visual name='base_fixed_joint_lump__ultraSound_right_visual_14'>
        <pose>-0.053499999999999999 -0.082600000000000007 0.0086800000000000002 0 0.26179999999999998 -1.570796326794897</pose>
        <geometry>
          <mesh>
            <scale>1 1 1</scale>
            <uri>models/unitree_go2/meshes/ultraSound.dae</uri>
          </mesh>
        </geometry>
        <material>
          <diffuse>0 0 0 1</diffuse>
          <ambient>0 0 0 1</ambient>
        </material>
      </visual>
      <sensor name="imu" type="imu">
        <always_on>1</always_on>
        <update_rate>100</update_rate>
        <visualize>true</visualize>
        <topic>/model/go2/link/base/sensor/imu/imu</topic>
      </sensor>
    </link>
    <joint name='lf_haa_joint' type='revolute'>
      <pose relative_to='base'>0.18809999999999999 0.04675 0 0 0 0</pose>
      <parent>base</parent>
      <child>lf_hipassembly</child>
      <axis>
        <xyz>1 0 0</xyz>
        <limit>
          <lower>-0.86299999999999999</lower>
          <upper>0.86299999999999999</upper>
          <effort>23.699999999999999</effort>
          <velocity>30.100000000000001</velocity>
        </limit>
        <dynamics>
          <damping>0.1</damping>
          <friction>0.05</friction>
          <spring_reference>0</spring_reference>
          <spring_stiffness>0</spring_stiffness>
        </dynamics>
      </axis>
    </joint>
    <link name='lf_hipassembly'>
      <pose relative_to='lf_haa_joint'>0 0 0 0 0 0</pose>
      <inertial>
        <pose>-0.0049165985294117639 -0.0076261499999999991 -8.865e-05 0 0 0</pose>
        <mass>0.67999999999999994</mass>
        <inertia>
          <ixx>0.0003993797857294</ixx>
          <ixy>-1.4590105668949999e-05</ixy>
          <ixz>1.2460991185500001e-06</ixz>
          <iyy>0.00073341939237609854</iyy>
          <iyz>1.5753255103e-06</iyz>
          <izz>0.00046842209057609862</izz>
        </inertia>
      </inertial>
      <collision name='lf_hipassembly_collision'>
        <pose>0 0.080000000000000002 0 1.5707963267948959 0 0</pose>
        <geometry>
          <cylinder>
            <length>0.040000000000000001</length>
            <radius>0.045999999999999999</radius>
          </cylinder>
        </geometry>
      </collision>
      <collision name='lf_hipassembly_fixed_joint_lump__lf_upperleg_rotor_collision_1'>
        <pose>0 -0.00014999999999999999 0 1.5707963267948959 0 0</pose>
        <geometry>
          <cylinder>
            <length>0.02</length>
            <radius>0.035000000000000003</radius>
          </cylinder>
        </geometry>
      </collision>
      <visual name='lf_hipassembly_visual'>
        <pose>0 0 0 0 0 0</pose>
        <geometry>
          <mesh>
            <scale>1 1 1</scale>
            <uri>models/unitree_go2/meshes/leg/hipassembly.dae</uri>
          </mesh>
        </geometry>
      </visual>
      <visual name='lf_hipassembly_fixed_joint_lump__lf_upperleg_rotor_visual_1'>
        <pose>0 -0.00014999999999999999 0 1.5707963267948959 0 0</pose>
        <geometry>
          <cylinder>
            <length>0.02</length>
            <radius>0.035000000000000003</radius>
          </cylinder>
        </geometry>
        <material>
          <diffuse>0 1 0 1</diffuse>
          <ambient>0 1 0 1</ambient>
        </material>
      </visual>
    </link>
    <joint name='lf_hfe_joint' type='revolute'>
      <pose relative_to='lf_hipassembly'>0 0.080000000000000002 0 0 0 0</pose>
      <parent>lf_hipassembly</parent>
      <child>lf_upperleg</child>
      <axis>
        <xyz>0 1 0</xyz>
        <limit>
          <lower>-0.68600000000000005</lower>
          <upper>4.5010000000000003</upper>
          <effort>23.699999999999999</effort>
          <velocity>30.100000000000001</velocity>
        </limit>
        <dynamics>
          <damping>0.1</damping>
          <friction>0.05</friction>
          <spring_reference>0</spring_reference>
          <spring_stiffness>0</spring_stiffness>
        </dynamics>
      </axis>
    </joint>
    <link name='lf_upperleg'>
      <pose relative_to='lf_hfe_joint'>0 0 0 0 0 0</pose>
      <inertial>
        <pose>-0.0030472150644202181 -0.019314995044598611 -0.03050041625371655 0 0 0</pose>
        <mass>1.0089999999999999</mass>
        <inertia>
          <ixx>0.0045987964610901466</ixx>
          <ixy>6.1373912803924688e-05</ixy>
          <ixz>-0.00022752911680967291</ixz>
          <iyy>0.0046892240622995037</iyy>
          <iyz>0.00061080828661791886</iyz>
          <izz>0.00081744785689930629</izz>
        </inertia>
      </inertial>
      <collision name='lf_upperleg_collision'>
        <pose>0 0 -0.1065 0 1.5707963267948966 0</pose>
        <geometry>
          <box>
            <size>0.21299999999999999 0.024500000000000001 0.034000000000000002</size>
          </box>
        </geometry>
      </collision>
      <collision name='lf_upperleg_fixed_joint_lump__lf_lowerleg_rotor_collision_1'>
        <pose>0 -0.032349999999999997 0 1.5707963267948959 0 0</pose>
        <geometry>
          <cylinder>
            <length>0.02</length>
            <radius>0.035000000000000003</radius>
          </cylinder>
        </geometry>
      </collision>
      <visual name='lf_upperleg_visual'>
        <pose>0 0 0 0 0 0</pose>
        <geometry>
          <mesh>
            <scale>1 1 1</scale>
            <uri>models/unitree_go2/meshes/leg/upperleg.dae</uri>
          </mesh>
        </geometry>
      </visual>
      <visual name='lf_upperleg_fixed_joint_lump__lf_lowerleg_rotor_visual_1'>
        <pose>0 -0.032349999999999997 0 1.5707963267948959 0 0</pose>
        <geometry>
          <cylinder>
            <length>0.02</length>
            <radius>0.035000000000000003</radius>
          </cylinder>
        </geometry>
        <material>
          <diffuse>0 1 0 1</diffuse>
          <ambient>0 1 0 1</ambient>
        </material>
      </visual>
    </link>
    <joint name='lf_kfe_joint' type='revolute'>
      <pose relative_to='lf_upperleg'>0 0 -0.21299999999999999 0 0 0</pose>
      <parent>lf_upperleg</parent>
      <child>lf_lowerleg</child>
      <axis>
        <xyz>0 1 0</xyz>
        <limit>
          <lower>-2.8180000000000001</lower>
          <upper>-0.88800000000000001</upper>
          <effort>35.549999999999997</effort>
          <velocity>20.059999999999999</velocity>
        </limit>
        <dynamics>
          <damping>0.1</damping>
          <friction>0.05</friction>
          <spring_reference>0</spring_reference>
          <spring_stiffness>0</spring_stiffness>
        </dynamics>
      </axis>
    </joint>
    <link name='lf_lowerleg'>
      <pose relative_to='lf_kfe_joint'>0 0 0 0 0 0</pose>
      <inertial>
        <pose>0.0061970000000000003 0.001408 -0.11669499999999999 0 0 0</pose>
        <mass>0.13586200000000001</mass>
        <inertia>
          <ixx>0.001088793059</ixx>
          <ixy>-2.55679e-07</ixy>
          <ixz>7.1178139999999998e-06</ixz>
          <iyy>0.0011004287479999999</iyy>
          <iyz>2.0772639999999999e-06</iyz>
          <izz>2.4787445999999998e-05</izz>
        </inertia>
      </inertial>
      <collision name='lf_lowerleg_collision'>
        <pose>0 0 -0.1065 0 1.5707963267948966 0</pose>
        <geometry>
          <box>
            <size>0.21299999999999999 0.016 0.016</size>
          </box>
        </geometry>
      </collision>
      <visual name='lf_lowerleg_visual'>
        <pose>0 0 0 0 0 0</pose>
        <geometry>
          <mesh>
            <scale>1 1 1</scale>
            <uri>models/unitree_go2/meshes/leg/lowerleg.dae</uri>
          </mesh>
        </geometry>
      </visual>
    </link>
    <joint name='lf_foot_joint' type='revolute'>
      <pose relative_to='lf_lowerleg'>0 0 -0.21299999999999999 0 0 0</pose>
      <parent>lf_lowerleg</parent>
      <child>lf_foot</child>
      <axis>
        <xyz>1 0 0</xyz>
        <limit>
          <lower>1</lower>
          <upper>1</upper>
          <effort>1</effort>
          <velocity>1</velocity>
        </limit>
        <dynamics>
          <spring_reference>0</spring_reference>
          <spring_stiffness>0</spring_stiffness>
        </dynamics>
      </axis>
    </joint>
    <link name='lf_foot'>
      <pose relative_to='lf_foot_joint'>0 0 0 0 0 0</pose>
      <inertial>
        <pose>0 0 0 0 0 0</pose>
        <mass>6.0000000000000003e-12</mass>
        <inertia>
          <ixx>9.6000000000000013e-06</ixx>
          <ixy>0</ixy>
          <ixz>0</ixz>
          <iyy>9.6000000000000013e-06</iyy>
          <iyz>0</iyz>
          <izz>9.6000000000000013e-06</izz>
        </inertia>
      </inertial>
      <collision name='lf_foot_collision'>
        <pose>0 0 0 0 0 0</pose>
        <geometry>
          <sphere>
            <radius>0.02</radius>
          </sphere>
        </geometry>
      </collision>
      <visual name='lf_foot_visual'>
        <pose>0 0 0 0 0 0</pose>
        <geometry>
          <sphere>
            <radius>0.01</radius>
          </sphere>
        </geometry>
      </visual>
    </link>
    <joint name='lh_haa_joint' type='revolute'>
      <pose relative_to='base'>-0.18809999999999999 0.04675 0 0 0 0</pose>
      <parent>base</parent>
      <child>lh_hipassembly</child>
      <axis>
        <xyz>1 0 0</xyz>
        <limit>
          <lower>-0.86299999999999999</lower>
          <upper>0.86299999999999999</upper>
          <effort>23.699999999999999</effort>
          <velocity>30.100000000000001</velocity>
        </limit>
        <dynamics>
          <damping>0.1</damping>
          <friction>0.05</friction>
          <spring_reference>0</spring_reference>
          <spring_stiffness>0</spring_stiffness>
        </dynamics>
      </axis>
    </joint>
    <link name='lh_hipassembly'>
      <pose relative_to='lh_haa_joint'>0 0 0 0 0 0</pose>
      <inertial>
        <pose>0.0049165985294117639 -0.0076261499999999991 -8.865e-05 0 0 0</pose>
        <mass>0.67999999999999994</mass>
        <inertia>
          <ixx>0.0003993797857294</ixx>
          <ixy>1.4590105668949999e-05</ixy>
          <ixz>-1.2460991185500001e-06</ixz>
          <iyy>0.00073341939237609854</iyy>
          <iyz>1.5753255103e-06</iyz>
          <izz>0.00046842209057609862</izz>
        </inertia>
      </inertial>
      <collision name='lh_hipassembly_collision'>
        <pose>0 0.080000000000000002 0 1.5707963267948959 0 0</pose>
        <geometry>
          <cylinder>
            <length>0.040000000000000001</length>
            <radius>0.045999999999999999</radius>
          </cylinder>
        </geometry>
      </collision>
      <collision name='lh_hipassembly_fixed_joint_lump__lh_upperleg_rotor_collision_1'>
        <pose>0 -0.00014999999999999999 0 1.5707963267948959 0 0</pose>
        <geometry>
          <cylinder>
            <length>0.02</length>
            <radius>0.035000000000000003</radius>
          </cylinder>
        </geometry>
      </collision>
      <visual name='lh_hipassembly_visual'>
        <pose>0 0 0 3.1415926535897931 1.224646799147353e-16 3.1415926535897931</pose>
        <geometry>
          <mesh>
            <scale>1 1 1</scale>
            <uri>models/unitree_go2/meshes/leg/hipassembly.dae</uri>
          </mesh>
        </geometry>
      </visual>
      <visual name='lh_hipassembly_fixed_joint_lump__lh_upperleg_rotor_visual_1'>
        <pose>0 -0.00014999999999999999 0 1.5707963267948959 0 0</pose>
        <geometry>
          <cylinder>
            <length>0.02</length>
            <radius>0.035000000000000003</radius>
          </cylinder>
        </geometry>
        <material>
          <diffuse>0 1 0 1</diffuse>
          <ambient>0 1 0 1</ambient>
        </material>
      </visual>
    </link>
    <joint name='lh_hfe_joint' type='revolute'>
      <pose relative_to='lh_hipassembly'>0 0.080000000000000002 0 0 0 0</pose>
      <parent>lh_hipassembly</parent>
      <child>lh_upperleg</child>
      <axis>
        <xyz>0 1 0</xyz>
        <limit>
          <lower>-0.68600000000000005</lower>
          <upper>4.5010000000000003</upper>
          <effort>23.699999999999999</effort>
          <velocity>30.100000000000001</velocity>
        </limit>
        <dynamics>
          <damping>0.1</damping>
          <friction>0.05</friction>
          <spring_reference>0</spring_reference>
          <spring_stiffness>0</spring_stiffness>
        </dynamics>
      </axis>
    </joint>
    <link name='lh_upperleg'>
      <pose relative_to='lh_hfe_joint'>0 0 0 0 0 0</pose>
      <inertial>
        <pose>-0.0030472150644202181 -0.019314995044598611 -0.03050041625371655 0 0 0</pose>
        <mass>1.0089999999999999</mass>
        <inertia>
          <ixx>0.0045987964610901466</ixx>
          <ixy>6.1373912803924688e-05</ixy>
          <ixz>-0.00022752911680967291</ixz>
          <iyy>0.0046892240622995037</iyy>
          <iyz>0.00061080828661791886</iyz>
          <izz>0.00081744785689930629</izz>
        </inertia>
      </inertial>
      <collision name='lh_upperleg_collision'>
        <pose>0 0 -0.1065 0 1.5707963267948966 0</pose>
        <geometry>
          <box>
            <size>0.21299999999999999 0.024500000000000001 0.034000000000000002</size>
          </box>
        </geometry>
      </collision>
      <collision name='lh_upperleg_fixed_joint_lump__lh_lowerleg_rotor_collision_1'>
        <pose>0 -0.032349999999999997 0 1.5707963267948959 0 0</pose>
        <geometry>
          <cylinder>
            <length>0.02</length>
            <radius>0.035000000000000003</radius>
          </cylinder>
        </geometry>
      </collision>
      <visual name='lh_upperleg_visual'>
        <pose>0 0 0 0 0 0</pose>
        <geometry>
          <mesh>
            <scale>1 1 1</scale>
            <uri>models/unitree_go2/meshes/leg/upperleg.dae</uri>
          </mesh>
        </geometry>
      </visual>
      <visual name='lh_upperleg_fixed_joint_lump__lh_lowerleg_rotor_visual_1'>
        <pose>0 -0.032349999999999997 0 1.5707963267948959 0 0</pose>
        <geometry>
          <cylinder>
            <length>0.02</length>
            <radius>0.035000000000000003</radius>
          </cylinder>
        </geometry>
        <material>
          <diffuse>0 1 0 1</diffuse>
          <ambient>0 1 0 1</ambient>
        </material>
      </visual>
    </link>
    <joint name='lh_kfe_joint' type='revolute'>
      <pose relative_to='lh_upperleg'>0 0 -0.21299999999999999 0 0 0</pose>
      <parent>lh_upperleg</parent>
      <child>lh_lowerleg</child>
      <axis>
        <xyz>0 1 0</xyz>
        <limit>
          <lower>-2.8180000000000001</lower>
          <upper>-0.88800000000000001</upper>
          <effort>35.549999999999997</effort>
          <velocity>20.059999999999999</velocity>
        </limit>
        <dynamics>
          <damping>0.1</damping>
          <friction>0.05</friction>
          <spring_reference>0</spring_reference>
          <spring_stiffness>0</spring_stiffness>
        </dynamics>
      </axis>
    </joint>
    <link name='lh_lowerleg'>
      <pose relative_to='lh_kfe_joint'>0 0 0 0 0 0</pose>
      <inertial>
        <pose>0.0061970000000000003 0.001408 -0.11669499999999999 0 0 0</pose>
        <mass>0.13586200000000001</mass>
        <inertia>
          <ixx>0.001088793059</ixx>
          <ixy>-2.55679e-07</ixy>
          <ixz>7.1178139999999998e-06</ixz>
          <iyy>0.0011004287479999999</iyy>
          <iyz>2.0772639999999999e-06</iyz>
          <izz>2.4787445999999998e-05</izz>
        </inertia>
      </inertial>
      <collision name='lh_lowerleg_collision'>
        <pose>0 0 -0.1065 0 1.5707963267948966 0</pose>
        <geometry>
          <box>
            <size>0.21299999999999999 0.016 0.016</size>
          </box>
        </geometry>
      </collision>
      <visual name='lh_lowerleg_visual'>
        <pose>0 0 0 0 0 0</pose>
        <geometry>
          <mesh>
            <scale>1 1 1</scale>
            <uri>models/unitree_go2/meshes/leg/lowerleg.dae</uri>
          </mesh>
        </geometry>
      </visual>
    </link>
    <joint name='lh_foot_joint' type='revolute'>
      <pose relative_to='lh_lowerleg'>0 0 -0.21299999999999999 0 0 0</pose>
      <parent>lh_lowerleg</parent>
      <child>lh_foot</child>
      <axis>
        <xyz>1 0 0</xyz>
        <limit>
          <lower>1</lower>
          <upper>1</upper>
          <effort>1</effort>
          <velocity>1</velocity>
        </limit>
        <dynamics>
          <spring_reference>0</spring_reference>
          <spring_stiffness>0</spring_stiffness>
        </dynamics>
      </axis>
    </joint>
    <link name='lh_foot'>
      <pose relative_to='lh_foot_joint'>0 0 0 0 0 0</pose>
      <inertial>
        <pose>0 0 0 0 0 0</pose>
        <mass>6.0000000000000003e-12</mass>
        <inertia>
          <ixx>9.6000000000000013e-06</ixx>
          <ixy>0</ixy>
          <ixz>0</ixz>
          <iyy>9.6000000000000013e-06</iyy>
          <iyz>0</iyz>
          <izz>9.6000000000000013e-06</izz>
        </inertia>
      </inertial>
      <collision name='lh_foot_collision'>
        <pose>0 0 0 0 0 0</pose>
        <geometry>
          <sphere>
            <radius>0.02</radius>
          </sphere>
        </geometry>
      </collision>
      <visual name='lh_foot_visual'>
        <pose>0 0 0 0 0 0</pose>
        <geometry>
          <sphere>
            <radius>0.01</radius>
          </sphere>
        </geometry>
      </visual>
    </link>
    <joint name='rf_haa_joint' type='revolute'>
      <pose relative_to='base'>0.18809999999999999 -0.04675 0 0 0 0</pose>
      <parent>base</parent>
      <child>rf_hipassembly</child>
      <axis>
        <xyz>1 0 0</xyz>
        <limit>
          <lower>-0.86299999999999999</lower>
          <upper>0.86299999999999999</upper>
          <effort>23.699999999999999</effort>
          <velocity>30.100000000000001</velocity>
        </limit>
        <dynamics>
          <damping>0.1</damping>
          <friction>0.05</friction>
          <spring_reference>0</spring_reference>
          <spring_stiffness>0</spring_stiffness>
        </dynamics>
      </axis>
    </joint>
    <link name='rf_hipassembly'>
      <pose relative_to='rf_haa_joint'>0 0 0 0 0 0</pose>
      <inertial>
        <pose>-0.0049165985294117639 0.0076261499999999991 -8.865e-05 0 0 0</pose>
        <mass>0.67999999999999994</mass>
        <inertia>
          <ixx>0.0003993797857294</ixx>
          <ixy>1.4590105668949999e-05</ixy>
          <ixz>1.2460991185500001e-06</ixz>
          <iyy>0.00073341939237609854</iyy>
          <iyz>-1.5753255103e-06</iyz>
          <izz>0.00046842209057609862</izz>
        </inertia>
      </inertial>
      <collision name='rf_hipassembly_collision'>
        <pose>0 -0.080000000000000002 0 1.5707963267948959 0 0</pose>
        <geometry>
          <cylinder>
            <length>0.040000000000000001</length>
            <radius>0.045999999999999999</radius>
          </cylinder>
        </geometry>
      </collision>
      <collision name='rf_hipassembly_fixed_joint_lump__rf_upperleg_rotor_collision_1'>
        <pose>0 0.00014999999999999999 0 1.5707963267948959 0 0</pose>
        <geometry>
          <cylinder>
            <length>0.02</length>
            <radius>0.035000000000000003</radius>
          </cylinder>
        </geometry>
      </collision>
      <visual name='rf_hipassembly_visual'>
        <pose>0 0 0 3.1415926535897931 0 0</pose>
        <geometry>
          <mesh>
            <scale>1 1 1</scale>
            <uri>models/unitree_go2/meshes/leg/hipassembly.dae</uri>
          </mesh>
        </geometry>
      </visual>
      <visual name='rf_hipassembly_fixed_joint_lump__rf_upperleg_rotor_visual_1'>
        <pose>0 0.00014999999999999999 0 1.5707963267948959 0 0</pose>
        <geometry>
          <cylinder>
            <length>0.02</length>
            <radius>0.035000000000000003</radius>
          </cylinder>
        </geometry>
        <material>
          <diffuse>0 1 0 1</diffuse>
          <ambient>0 1 0 1</ambient>
        </material>
      </visual>
    </link>
    <joint name='rf_hfe_joint' type='revolute'>
      <pose relative_to='rf_hipassembly'>0 -0.080000000000000002 0 0 0 0</pose>
      <parent>rf_hipassembly</parent>
      <child>rf_upperleg</child>
      <axis>
        <xyz>0 1 0</xyz>
        <limit>
          <lower>-0.68600000000000005</lower>
          <upper>4.5010000000000003</upper>
          <effort>23.699999999999999</effort>
          <velocity>30.100000000000001</velocity>
        </limit>
        <dynamics>
          <damping>0.1</damping>
          <friction>0.05</friction>
          <spring_reference>0</spring_reference>
          <spring_stiffness>0</spring_stiffness>
        </dynamics>
      </axis>
    </joint>
    <link name='rf_upperleg'>
      <pose relative_to='rf_hfe_joint'>0 0 0 0 0 0</pose>
      <inertial>
        <pose>-0.0030472150644202181 0.019314995044598611 -0.03050041625371655 0 0 0</pose>
        <mass>1.0089999999999999</mass>
        <inertia>
          <ixx>0.0045987964610901466</ixx>
          <ixy>-6.1373912803924688e-05</ixy>
          <ixz>-0.00022752911680967291</ixz>
          <iyy>0.0046892240622995037</iyy>
          <iyz>-0.00061080828661791886</iyz>
          <izz>0.00081744785689930629</izz>
        </inertia>
      </inertial>
      <collision name='rf_upperleg_collision'>
        <pose>0 0 -0.1065 0 1.5707963267948966 0</pose>
        <geometry>
          <box>
            <size>0.21299999999999999 0.024500000000000001 0.034000000000000002</size>
          </box>
        </geometry>
      </collision>
      <collision name='rf_upperleg_fixed_joint_lump__rf_lowerleg_rotor_collision_1'>
        <pose>0 0.032349999999999997 0 1.5707963267948959 0 0</pose>
        <geometry>
          <cylinder>
            <length>0.02</length>
            <radius>0.035000000000000003</radius>
          </cylinder>
        </geometry>
      </collision>
      <visual name='rf_upperleg_visual'>
        <pose>0 0 0 0 0 0</pose>
        <geometry>
          <mesh>
            <scale>1 1 1</scale>
            <uri>models/unitree_go2/meshes/upperleg_mirror.dae</uri>
          </mesh>
        </geometry>
      </visual>
      <visual name='rf_upperleg_fixed_joint_lump__rf_lowerleg_rotor_visual_1'>
        <pose>0 0.032349999999999997 0 1.5707963267948959 0 0</pose>
        <geometry>
          <cylinder>
            <length>0.02</length>
            <radius>0.035000000000000003</radius>
          </cylinder>
        </geometry>
        <material>
          <diffuse>0 1 0 1</diffuse>
          <ambient>0 1 0 1</ambient>
        </material>
      </visual>
    </link>
    <joint name='rf_kfe_joint' type='revolute'>
      <pose relative_to='rf_upperleg'>0 0 -0.21299999999999999 0 0 0</pose>
      <parent>rf_upperleg</parent>
      <child>rf_lowerleg</child>
      <axis>
        <xyz>0 1 0</xyz>
        <limit>
          <lower>-2.8180000000000001</lower>
          <upper>-0.88800000000000001</upper>
          <effort>35.549999999999997</effort>
          <velocity>20.059999999999999</velocity>
        </limit>
        <dynamics>
          <damping>0.1</damping>
          <friction>0.05</friction>
          <spring_reference>0</spring_reference>
          <spring_stiffness>0</spring_stiffness>
        </dynamics>
      </axis>
    </joint>
    <link name='rf_lowerleg'>
      <pose relative_to='rf_kfe_joint'>0 0 0 0 0 0</pose>
      <inertial>
        <pose>0.0061970000000000003 0.001408 -0.11669499999999999 0 0 0</pose>
        <mass>0.13586200000000001</mass>
        <inertia>
          <ixx>0.001088793059</ixx>
          <ixy>-2.55679e-07</ixy>
          <ixz>7.1178139999999998e-06</ixz>
          <iyy>0.0011004287479999999</iyy>
          <iyz>2.0772639999999999e-06</iyz>
          <izz>2.4787445999999998e-05</izz>
        </inertia>
      </inertial>
      <collision name='rf_lowerleg_collision'>
        <pose>0 0 -0.1065 0 1.5707963267948966 0</pose>
        <geometry>
          <box>
            <size>0.21299999999999999 0.016 0.016</size>
          </box>
        </geometry>
      </collision>
      <visual name='rf_lowerleg_visual'>
        <pose>0 0 0 0 0 0</pose>
        <geometry>
          <mesh>
            <scale>1 1 1</scale>
            <uri>models/unitree_go2/meshes/leg/lowerleg.dae</uri>
          </mesh>
        </geometry>
      </visual>
    </link>
    <joint name='rf_foot_joint' type='revolute'>
      <pose relative_to='rf_lowerleg'>0 0 -0.21299999999999999 0 0 0</pose>
      <parent>rf_lowerleg</parent>
      <child>rf_foot</child>
      <axis>
        <xyz>1 0 0</xyz>
        <limit>
          <lower>1</lower>
          <upper>1</upper>
          <effort>1</effort>
          <velocity>1</velocity>
        </limit>
        <dynamics>
          <spring_reference>0</spring_reference>
          <spring_stiffness>0</spring_stiffness>
        </dynamics>
      </axis>
    </joint>
    <link name='rf_foot'>
      <pose relative_to='rf_foot_joint'>0 0 0 0 0 0</pose>
      <inertial>
        <pose>0 0 0 0 0 0</pose>
        <mass>6.0000000000000003e-12</mass>
        <inertia>
          <ixx>9.6000000000000013e-06</ixx>
          <ixy>0</ixy>
          <ixz>0</ixz>
          <iyy>9.6000000000000013e-06</iyy>
          <iyz>0</iyz>
          <izz>9.6000000000000013e-06</izz>
        </inertia>
      </inertial>
      <collision name='rf_foot_collision'>
        <pose>0 0 0 0 0 0</pose>
        <geometry>
          <sphere>
            <radius>0.02</radius>
          </sphere>
        </geometry>
      </collision>
      <visual name='rf_foot_visual'>
        <pose>0 0 0 0 0 0</pose>
        <geometry>
          <sphere>
            <radius>0.01</radius>
          </sphere>
        </geometry>
      </visual>
    </link>
    <joint name='rh_haa_joint' type='revolute'>
      <pose relative_to='base'>-0.18809999999999999 -0.04675 0 0 0 0</pose>
      <parent>base</parent>
      <child>rh_hipassembly</child>
      <axis>
        <xyz>1 0 0</xyz>
        <limit>
          <lower>-0.86299999999999999</lower>
          <upper>0.86299999999999999</upper>
          <effort>23.699999999999999</effort>
          <velocity>30.100000000000001</velocity>
        </limit>
        <dynamics>
          <damping>0.1</damping>
          <friction>0.05</friction>
          <spring_reference>0</spring_reference>
          <spring_stiffness>0</spring_stiffness>
        </dynamics>
      </axis>
    </joint>
    <link name='rh_hipassembly'>
      <pose relative_to='rh_haa_joint'>0 0 0 0 0 0</pose>
      <inertial>
        <pose>0.0049165985294117639 0.0076261499999999991 -8.865e-05 0 0 0</pose>
        <mass>0.67999999999999994</mass>
        <inertia>
          <ixx>0.0003993797857294</ixx>
          <ixy>-1.4590105668949999e-05</ixy>
          <ixz>-1.2460991185500001e-06</ixz>
          <iyy>0.00073341939237609854</iyy>
          <iyz>-1.5753255103e-06</iyz>
          <izz>0.00046842209057609862</izz>
        </inertia>
      </inertial>
      <collision name='rh_hipassembly_collision'>
        <pose>0 -0.080000000000000002 0 1.5707963267948959 0 0</pose>
        <geometry>
          <cylinder>
            <length>0.040000000000000001</length>
            <radius>0.045999999999999999</radius>
          </cylinder>
        </geometry>
      </collision>
      <collision name='rh_hipassembly_fixed_joint_lump__rh_upperleg_rotor_collision_1'>
        <pose>0 0.00014999999999999999 0 1.5707963267948959 0 0</pose>
        <geometry>
          <cylinder>
            <length>0.02</length>
            <radius>0.035000000000000003</radius>
          </cylinder>
        </geometry>
      </collision>
      <visual name='rh_hipassembly_visual'>
        <pose>0 0 0 -1.224646799147353e-16 1.224646799147353e-16 3.1415926535897931</pose>
        <geometry>
          <mesh>
            <scale>1 1 1</scale>
            <uri>models/unitree_go2/meshes/leg/hipassembly.dae</uri>
          </mesh>
        </geometry>
      </visual>
      <visual name='rh_hipassembly_fixed_joint_lump__rh_upperleg_rotor_visual_1'>
        <pose>0 0.00014999999999999999 0 1.5707963267948959 0 0</pose>
        <geometry>
          <cylinder>
            <length>0.02</length>
            <radius>0.035000000000000003</radius>
          </cylinder>
        </geometry>
        <material>
          <diffuse>0 1 0 1</diffuse>
          <ambient>0 1 0 1</ambient>
        </material>
      </visual>
    </link>
    <joint name='rh_hfe_joint' type='revolute'>
      <pose relative_to='rh_hipassembly'>0 -0.080000000000000002 0 0 0 0</pose>
      <parent>rh_hipassembly</parent>
      <child>rh_upperleg</child>
      <axis>
        <xyz>0 1 0</xyz>
        <limit>
          <lower>-0.68600000000000005</lower>
          <upper>4.5010000000000003</upper>
          <effort>23.699999999999999</effort>
          <velocity>30.100000000000001</velocity>
        </limit>
        <dynamics>
          <damping>0.1</damping>
          <friction>0.05</friction>
          <spring_reference>0</spring_reference>
          <spring_stiffness>0</spring_stiffness>
        </dynamics>
      </axis>
    </joint>
    <link name='rh_upperleg'>
      <pose relative_to='rh_hfe_joint'>0 0 0 0 0 0</pose>
      <inertial>
        <pose>-0.0030472150644202181 0.019314995044598611 -0.03050041625371655 0 0 0</pose>
        <mass>1.0089999999999999</mass>
        <inertia>
          <ixx>0.0045987964610901466</ixx>
          <ixy>-6.1373912803924688e-05</ixy>
          <ixz>-0.00022752911680967291</ixz>
          <iyy>0.0046892240622995037</iyy>
          <iyz>-0.00061080828661791886</iyz>
          <izz>0.00081744785689930629</izz>
        </inertia>
      </inertial>
      <collision name='rh_upperleg_collision'>
        <pose>0 0 -0.1065 0 1.5707963267948966 0</pose>
        <geometry>
          <box>
            <size>0.21299999999999999 0.024500000000000001 0.034000000000000002</size>
          </box>
        </geometry>
      </collision>
      <collision name='rh_upperleg_fixed_joint_lump__rh_lowerleg_rotor_collision_1'>
        <pose>0 0.032349999999999997 0 1.5707963267948959 0 0</pose>
        <geometry>
          <cylinder>
            <length>0.02</length>
            <radius>0.035000000000000003</radius>
          </cylinder>
        </geometry>
      </collision>
      <visual name='rh_upperleg_visual'>
        <pose>0 0 0 0 0 0</pose>
        <geometry>
          <mesh>
            <scale>1 1 1</scale>
            <uri>models/unitree_go2/meshes/upperleg_mirror.dae</uri>
          </mesh>
        </geometry>
      </visual>
      <visual name='rh_upperleg_fixed_joint_lump__rh_lowerleg_rotor_visual_1'>
        <pose>0 0.032349999999999997 0 1.5707963267948959 0 0</pose>
        <geometry>
          <cylinder>
            <length>0.02</length>
            <radius>0.035000000000000003</radius>
          </cylinder>
        </geometry>
        <material>
          <diffuse>0 1 0 1</diffuse>
          <ambient>0 1 0 1</ambient>
        </material>
      </visual>
    </link>
    <joint name='rh_kfe_joint' type='revolute'>
      <pose relative_to='rh_upperleg'>0 0 -0.21299999999999999 0 0 0</pose>
      <parent>rh_upperleg</parent>
      <child>rh_lowerleg</child>
      <axis>
        <xyz>0 1 0</xyz>
        <limit>
          <lower>-2.8180000000000001</lower>
          <upper>-0.88800000000000001</upper>
          <effort>35.549999999999997</effort>
          <velocity>20.059999999999999</velocity>
        </limit>
        <dynamics>
          <damping>0.1</damping>
          <friction>0.05</friction>
          <spring_reference>0</spring_reference>
          <spring_stiffness>0</spring_stiffness>
        </dynamics>
      </axis>
    </joint>
    <link name='rh_lowerleg'>
      <pose relative_to='rh_kfe_joint'>0 0 0 0 0 0</pose>
      <inertial>
        <pose>0.0061970000000000003 0.001408 -0.11669499999999999 0 0 0</pose>
        <mass>0.13586200000000001</mass>
        <inertia>
          <ixx>0.001088793059</ixx>
          <ixy>-2.55679e-07</ixy>
          <ixz>7.1178139999999998e-06</ixz>
          <iyy>0.0011004287479999999</iyy>
          <iyz>2.0772639999999999e-06</iyz>
          <izz>2.4787445999999998e-05</izz>
        </inertia>
      </inertial>
      <collision name='rh_lowerleg_collision'>
        <pose>0 0 -0.1065 0 1.5707963267948966 0</pose>
        <geometry>
          <box>
            <size>0.21299999999999999 0.016 0.016</size>
          </box>
        </geometry>
      </collision>
      <visual name='rh_lowerleg_visual'>
        <pose>0 0 0 0 0 0</pose>
        <geometry>
          <mesh>
            <scale>1 1 1</scale>
            <uri>models/unitree_go2/meshes/leg/lowerleg.dae</uri>
          </mesh>
        </geometry>
      </visual>
    </link>
    <joint name='rh_foot_joint' type='revolute'>
      <pose relative_to='rh_lowerleg'>0 0 -0.21299999999999999 0 0 0</pose>
      <parent>rh_lowerleg</parent>
      <child>rh_foot</child>
      <axis>
        <xyz>1 0 0</xyz>
        <limit>
          <lower>1</lower>
          <upper>1</upper>
          <effort>1</effort>
          <velocity>1</velocity>
        </limit>
        <dynamics>
          <spring_reference>0</spring_reference>
          <spring_stiffness>0</spring_stiffness>
        </dynamics>
      </axis>
    </joint>
    <link name='rh_foot'>
      <pose relative_to='rh_foot_joint'>0 0 0 0 0 0</pose>
      <inertial>
        <pose>0 0 0 0 0 0</pose>
        <mass>6.0000000000000003e-12</mass>
        <inertia>
          <ixx>9.6000000000000013e-06</ixx>
          <ixy>0</ixy>
          <ixz>0</ixz>
          <iyy>9.6000000000000013e-06</iyy>
          <iyz>0</iyz>
          <izz>9.6000000000000013e-06</izz>
        </inertia>
      </inertial>
      <collision name='rh_foot_collision'>
        <pose>0 0 0 0 0 0</pose>
        <geometry>
          <sphere>
            <radius>0.02</radius>
          </sphere>
        </geometry>
      </collision>
      <visual name='rh_foot_visual'>
        <pose>0 0 0 0 0 0</pose>
        <geometry>
          <sphere>
            <radius>0.01</radius>
          </sphere>
        </geometry>
      </visual>
    </link>
    <frame name='camera_optical_joint_chin' attached_to='camera_chin'>
      <pose>0 0 0 -1.5707963267948959 -5.5511151231257827e-17 -1.5707963267948959</pose>
    </frame>
    <frame name='camera_optical_chin' attached_to='camera_optical_joint_chin'>
      <pose>0 0 0 0 0 0</pose>
    </frame>
    <frame name='camera_joint_chin' attached_to='trunk'>
      <pose>0.25219999999999998 0.012500000000000001 -0.0436 3.1415926535897931 1.5707963267948966 0</pose>
    </frame>
    <frame name='camera_chin' attached_to='camera_joint_chin'>
      <pose>0 0 0 0 0 0</pose>
    </frame>
    <frame name='camera_optical_joint_face' attached_to='camera_face'>
      <pose>0 0 0 -1.5707963267948959 -5.5511151231257827e-17 -1.5707963267948959</pose>
    </frame>
    <frame name='camera_optical_face' attached_to='camera_optical_joint_face'>
      <pose>0 0 0 0 0 0</pose>
    </frame>
    <frame name='camera_joint_face' attached_to='trunk'>
      <pose>0.27850000000000003 0.012500000000000001 0.0167 3.1415926535897931 0 0</pose>
    </frame>
    <frame name='camera_face' attached_to='camera_joint_face'>
      <pose>0 0 0 0 0 0</pose>
    </frame>
    <frame name='camera_laserscan_joint_left' attached_to='camera_left'>
      <pose>0 0 0 0 0.26180000000000031 0</pose>
    </frame>
    <frame name='camera_laserscan_link_left' attached_to='camera_laserscan_joint_left'>
      <pose>0 0 0 0 0 0</pose>
    </frame>
    <frame name='camera_optical_joint_left' attached_to='camera_left'>
      <pose>0 0 0 -1.5707963267948959 -5.5511151231257827e-17 -1.5707963267948959</pose>
    </frame>
    <frame name='camera_optical_left' attached_to='camera_optical_joint_left'>
      <pose>0 0 0 0 0 0</pose>
    </frame>
    <frame name='camera_joint_left' attached_to='trunk'>
      <pose>-0.066000000000000003 0.082000000000000003 -0.017600000000000001 3.1415926535897931 0.26179999999999998 1.5707963267948957</pose>
    </frame>
    <frame name='camera_left' attached_to='camera_joint_left'>
      <pose>0 0 0 0 0 0</pose>
    </frame>
    <frame name='camera_optical_joint_rearDown' attached_to='camera_rearDown'>
      <pose>0 0 0 -1.5707963267948959 -5.5511151231257827e-17 -1.5707963267948959</pose>
    </frame>
    <frame name='camera_optical_rearDown' attached_to='camera_optical_joint_rearDown'>
      <pose>0 0 0 0 0 0</pose>
    </frame>
    <frame name='camera_joint_rearDown' attached_to='trunk'>
      <pose>-0.082500000000000004 0.012500000000000001 -0.043650000000000001 3.1415926535897931 1.5707963267948966 0</pose>
    </frame>
    <frame name='camera_rearDown' attached_to='camera_joint_rearDown'>
      <pose>0 0 0 0 0 0</pose>
    </frame>
    <frame name='camera_laserscan_joint_right' attached_to='camera_right'>
      <pose>0 0 0 0 0.26180000000000031 0</pose>
    </frame>
    <frame name='camera_laserscan_link_right' attached_to='camera_laserscan_joint_right'>
      <pose>0 0 0 0 0 0</pose>
    </frame>
    <frame name='camera_optical_joint_right' attached_to='camera_right'>
      <pose>0 0 0 -1.5707963267948959 -5.5511151231257827e-17 -1.5707963267948959</pose>
    </frame>
    <frame name='camera_optical_right' attached_to='camera_optical_joint_right'>
      <pose>0 0 0 0 0 0</pose>
    </frame>
    <frame name='camera_joint_right' attached_to='trunk'>
      <pose>-0.041000000000000002 -0.082000000000000003 -0.017600000000000001 3.1415926535897931 0.26179999999999998 -1.570796326794897</pose>
    </frame>
    <frame name='camera_right' attached_to='camera_joint_right'>
      <pose>0 0 0 0 0 0</pose>
    </frame>
    <frame name='imu_joint' attached_to='trunk'>
      <pose>-0.01592 -0.066589999999999996 -0.0061700000000000001 0 0 0</pose>
    </frame>
    <frame name='imu_link' attached_to='imu_joint'>
      <pose>0 0 0 0 0 0</pose>
    </frame>
    <frame name='lf_hipassembly_rotor_joint' attached_to='trunk'>
      <pose>0.11215 0.04675 0 0 0 0</pose>
    </frame>
    <frame name='lf_hipassembly_rotor' attached_to='lf_hipassembly_rotor_joint'>
      <pose>0 0 0 0 0 0</pose>
    </frame>
    <frame name='lh_hipassembly_rotor_joint' attached_to='trunk'>
      <pose>-0.11215 0.04675 0 0 0 0</pose>
    </frame>
    <frame name='lh_hipassembly_rotor' attached_to='lh_hipassembly_rotor_joint'>
      <pose>0 0 0 0 0 0</pose>
    </frame>
    <frame name='rf_hipassembly_rotor_joint' attached_to='trunk'>
      <pose>0.11215 -0.04675 0 0 0 0</pose>
    </frame>
    <frame name='rf_hipassembly_rotor' attached_to='rf_hipassembly_rotor_joint'>
      <pose>0 0 0 0 0 0</pose>
    </frame>
    <frame name='rh_hipassembly_rotor_joint' attached_to='trunk'>
      <pose>-0.11215 -0.04675 0 0 0 0</pose>
    </frame>
    <frame name='rh_hipassembly_rotor' attached_to='rh_hipassembly_rotor_joint'>
      <pose>0 0 0 0 0 0</pose>
    </frame>
    <frame name='ultraSound_joint_face' attached_to='trunk'>
      <pose>0.2747 0 -0.0088000000000000005 0 0 0</pose>
    </frame>
    <frame name='ultraSound_face' attached_to='ultraSound_joint_face'>
      <pose>0 0 0 0 0 0</pose>
    </frame>
    <frame name='ultraSound_joint_left' attached_to='trunk'>
      <pose>-0.053499999999999999 0.082600000000000007 0.0086800000000000002 0 0.26179999999999998 1.570796326794897</pose>
    </frame>
    <frame name='ultraSound_left' attached_to='ultraSound_joint_left'>
      <pose>0 0 0 0 0 0</pose>
    </frame>
    <frame name='ultraSound_joint_right' attached_to='trunk'>
      <pose>-0.053499999999999999 -0.082600000000000007 0.0086800000000000002 0 0.26179999999999998 -1.570796326794897</pose>
    </frame>
    <frame name='ultraSound_right' attached_to='ultraSound_joint_right'>
      <pose>0 0 0 0 0 0</pose>
    </frame>
    <frame name='floating_base' attached_to='base'>
      <pose>0 0 0 0 0 0</pose>
    </frame>
    <frame name='trunk' attached_to='floating_base'>
      <pose>0 0 0 0 0 0</pose>
    </frame>
    <frame name='lf_upperleg_rotor_joint' attached_to='lf_hipassembly'>
      <pose>0 -0.00014999999999999999 0 0 0 0</pose>
    </frame>
    <frame name='lf_upperleg_rotor' attached_to='lf_upperleg_rotor_joint'>
      <pose>0 0 0 0 0 0</pose>
    </frame>
    <frame name='lf_lowerleg_rotor_joint' attached_to='lf_upperleg'>
      <pose>0 -0.032349999999999997 0 0 0 0</pose>
    </frame>
    <frame name='lf_lowerleg_rotor' attached_to='lf_lowerleg_rotor_joint'>
      <pose>0 0 0 0 0 0</pose>
    </frame>
    <frame name='lh_upperleg_rotor_joint' attached_to='lh_hipassembly'>
      <pose>0 -0.00014999999999999999 0 0 0 0</pose>
    </frame>
    <frame name='lh_upperleg_rotor' attached_to='lh_upperleg_rotor_joint'>
      <pose>0 0 0 0 0 0</pose>
    </frame>
    <frame name='lh_lowerleg_rotor_joint' attached_to='lh_upperleg'>
      <pose>0 -0.032349999999999997 0 0 0 0</pose>
    </frame>
    <frame name='lh_lowerleg_rotor' attached_to='lh_lowerleg_rotor_joint'>
      <pose>0 0 0 0 0 0</pose>
    </frame>
    <frame name='rf_upperleg_rotor_joint' attached_to='rf_hipassembly'>
      <pose>0 0.00014999999999999999 0 0 0 0</pose>
    </frame>
    <frame name='rf_upperleg_rotor' attached_to='rf_upperleg_rotor_joint'>
      <pose>0 0 0 0 0 0</pose>
    </frame>
    <frame name='rf_lowerleg_rotor_joint' attached_to='rf_upperleg'>
      <pose>0 0.032349999999999997 0 0 0 0</pose>
    </frame>
    <frame name='rf_lowerleg_rotor' attached_to='rf_lowerleg_rotor_joint'>
      <pose>0 0 0 0 0 0</pose>
    </frame>
    <frame name='rh_upperleg_rotor_joint' attached_to='rh_hipassembly'>
      <pose>0 0.00014999999999999999 0 0 0 0</pose>
    </frame>
    <frame name='rh_upperleg_rotor' attached_to='rh_upperleg_rotor_joint'>
      <pose>0 0 0 0 0 0</pose>
    </frame>
    <frame name='rh_lowerleg_rotor_joint' attached_to='rh_upperleg'>
      <pose>0 0.032349999999999997 0 0 0 0</pose>
    </frame>
    <frame name='rh_lowerleg_rotor' attached_to='rh_lowerleg_rotor_joint'>
      <pose>0 0 0 0 0 0</pose>
    </frame>
    <plugin filename="gz-sim-apply-joint-force-system" name="gz::sim::systems::ApplyJointForce">
      <joint_name>rf_haa_joint</joint_name>
    </plugin>
    <plugin filename="gz-sim-apply-joint-force-system" name="gz::sim::systems::ApplyJointForce">
      <joint_name>lf_haa_joint</joint_name>
    </plugin>
    <plugin filename="gz-sim-apply-joint-force-system" name="gz::sim::systems::ApplyJointForce">
      <joint_name>lf_haa_joint</joint_name>
    </plugin>
    <plugin filename="gz-sim-apply-joint-force-system" name="gz::sim::systems::ApplyJointForce">
      <joint_name>rf_haa_joint</joint_name>
    </plugin>
    <plugin filename="gz-sim-apply-joint-force-system" name="gz::sim::systems::ApplyJointForce">
      <joint_name>lh_haa_joint</joint_name>
    </plugin>
    <plugin filename="gz-sim-apply-joint-force-system" name="gz::sim::systems::ApplyJointForce">
      <joint_name>rh_haa_joint</joint_name>
    </plugin>
    <plugin filename="gz-sim-apply-joint-force-system" name="gz::sim::systems::ApplyJointForce">
      <joint_name>lf_hfe_joint</joint_name>
    </plugin>
    <plugin filename="gz-sim-apply-joint-force-system" name="gz::sim::systems::ApplyJointForce">
      <joint_name>rf_hfe_joint</joint_name>
    </plugin>
    <plugin filename="gz-sim-apply-joint-force-system" name="gz::sim::systems::ApplyJointForce">
      <joint_name>lh_hfe_joint</joint_name>
    </plugin>
    <plugin filename="gz-sim-apply-joint-force-system" name="gz::sim::systems::ApplyJointForce">
      <joint_name>rh_hfe_joint</joint_name>
    </plugin>
    <plugin filename="gz-sim-apply-joint-force-system" name="gz::sim::systems::ApplyJointForce">
      <joint_name>lf_kfe_joint</joint_name>
    </plugin>
    <plugin filename="gz-sim-apply-joint-force-system" name="gz::sim::systems::ApplyJointForce">
      <joint_name>rf_kfe_joint</joint_name>
    </plugin>
    <plugin filename="gz-sim-apply-joint-force-system" name="gz::sim::systems::ApplyJointForce">
      <joint_name>lh_kfe_joint</joint_name>
    </plugin>
    <plugin filename="gz-sim-apply-joint-force-system" name="gz::sim::systems::ApplyJointForce">
      <joint_name>rh_kfe_joint</joint_name>
    </plugin>

    <plugin filename="gz-sim-joint-state-publisher-system" name="gz::sim::systems::JointStatePublisher">
        <topic>/model/go2/joint_state</topic>
        <update_frequency>200</update_frequency>
        <joint_name>lf_haa_joint</joint_name>
        <joint_name>lf_hfe_joint</joint_name>
        <joint_name>lf_kfe_joint</joint_name>
        <joint_name>rf_haa_joint</joint_name>
        <joint_name>rf_hfe_joint</joint_name>
        <joint_name>rf_kfe_joint</joint_name>
        <joint_name>lh_haa_joint</joint_name>
        <joint_name>lh_hfe_joint</joint_name>
        <joint_name>lh_kfe_joint</joint_name>
        <joint_name>rh_haa_joint</joint_name>
        <joint_name>rh_hfe_joint</joint_name>
        <joint_name>rh_kfe_joint</joint_name>
    </plugin>

    <plugin filename="gz-sim-odometry-publisher-system" name="gz::sim::systems::OdometryPublisher">
      <odom_frame>odom</odom_frame>
      <robot_base_frame>base</robot_base_frame>
      <odom_publish_frequency>200</odom_publish_frequency>
      <dimensions>3</dimensions>
    </plugin>

    <plugin filename="gz-sim-pose-publisher-system" name="gz::sim::systems::PosePublisher">
      <publish_link_pose>false</publish_link_pose>
      <use_sensor_names>true</use_sensor_names>
      <publish_collision_pose>false</publish_collision_pose>
      <publish_visual_pose>false</publish_visual_pose>
      <publish_nested_model_pose>true</publish_nested_model_pose>
      <update_frequency>50</update_frequency>
    </plugin>
  </model>
</sdf>
